Workbook

Sheet Instructions
A1: SYSTEM1 · SOURCE REGISTRY
A2: Reference workbook · Review sources and use the Dashboard in the browser workbench
A4: START IN THE WORKBENCH
A5: 1. Open | B5: Project-root launcher | C5: Save and close Excel, then double-click Open Workbench.command in the project root. It opens the browser workbench.
A6: 2. Identify yourself | B6: Current reviewer | C6: Choose Ana Jokic, Daniel Restad or Weijie Tang once. Switch reviewer when another person takes over.
A7: 3. Review | B7: System1 → Pending review | C7: Choose a source from the left queue. Open its official link or original, then complete the action requested on screen.
A8: 4. Record | B8: Submit decision | C8: Use Submit decision after choosing the requested ratings. Other tasks have their own save button. Do not run a program after each review.
A9: 5. Follow up | B9: Review history / Overview | C9: Completed reviews move to Review history. Unresolved issues stay pending. Overview contains the live Dashboard and weekly accuracy chart.
A11: WHAT THIS WORKBOOK CONTAINS
A12: Instructions | B12: Read-only guidance | C12: This guide points to the browser workflow. Full instructions: workbench/USER_GUIDE.md in the Requirement Workstream.
A13: Categories | B13: Controlled vocabulary | C13: Program-maintained definitions and dropdown values. These are reference data, not a human review form.
A14: Source Register | B14: Canonical source state | C14: System1 manages source identities, snapshots, scores and selection here. Submit human changes in the browser, not directly in these cells.
A15: Dashboard | B15: Retired; hidden | C15: The browser Overview replaces the Excel Dashboard. Its old formulas and charts remain hidden for compatibility; do not unhide it for daily work.
A16: Human Operation Desktop | B16: Program-owned; hidden | C16: The browser replaces this editing surface. The hidden sheet still stores adapter staging and audit history. Do not delete it or edit its rows.
A18: REVIEW STATUS
A19: Pending review | B19: Action remains unresolved | C19: Includes source assessment, missing originals, reported issues and weekly checks. A previous score or draft is not a completed decision.
A20: Submitted / Waiting | B20: Not applied yet | C20: The workbench shows application progress. If Excel is open or another task holds the lock, processing waits and resumes automatically.
A21: Applied / Review history | B21: Recorded decision | C21: The reviewer, original note and result are preserved. An applied partial correction can still leave a source pending for other issues.
A22: INCLUDE / PENDING / EXCLUDE | B22: Effective source selection | C22: Selection is separate from file storage and download success. Inclusion requires a valid snapshot and completed governance gates.
A24: COMMON REVIEW ACTIONS
A25: Source assessment | B25: Rate five dimensions | C25: Click H / M / L for each requested dimension. Light fill is the previous score; dark fill is your current choice. Use Submit decision to apply the selected ratings.
A26: Correct a link | B26: Save corrected links | C26: Open the suggested URL, correct the appropriate field and save. Saving a URL does not download or verify a new original. Reported issues require explicit verification.
A27: Missing original | B27: Choose file | C27: Upload an authorised PDF, HTML or XLSX in the workbench. After the format check, confirm identity, completeness and permission, then submit.
A28: Notes / Keep pending | B28: Preserve unresolved questions | C28: Notes save as drafts without completing a task. Explain the reason when keeping a source pending, removing it from scope or reporting an error.
A29: Weekly random check | B29: Correct / Report an error | C29: Compare the sampled source with its original. An error creates a follow-up task; it does not count as a correct result.
A30: New candidate | B30: Maintainer-assisted intake | C30: A dedicated browser candidate form is not connected yet. Ask the maintainer to handle the named-human acceptance; never use ordinary ratings as candidate acceptance.
A32: SOURCE RULES
A33: Identity and retrieval | B33: Two distinct URLs | C33: official_url identifies the publisher page; retrieval_url identifies the downloadable original. Preserve the original format and authoritative language.
A34: Existing snapshots | B34: Preserve valid originals | C34: Failed retrieval or replacement must retain the current valid snapshot and failure evidence. An authorised upload is required for restricted material; never bypass a paywall.
A35: Downstream use | B35: Source eligibility is governed here | C35: Downstream parsing consumes the controlled source state and original. Stored files and source approval do not prove extraction accuracy or legal compliance.
A37: AUTOMATIC PROCESSING
A38: Weekly QA | B38: Service-owned schedule | C38: Every Monday, sample 5 eligible items per connected system in Europe/Oslo time. After downtime, create only the current week's missing batch. Keep incomplete weeks blank in accuracy charts.
A39: Browser decisions | B39: No manual rerun | C39: The running workbench applies submitted reviews automatically. Weekly QA is part of the service, not a Codex task. Closing the page does not stop the service.
A40: Maintenance schedules | B40: Separate, optional | C40: Source retrieval and maintenance schedules require explicit setup by a maintainer. Opening the workbench does not start Full Source Check, downloads or parsing.
A42: RECOVERY AND HELP
A43: Workbook repair prompt | B43: Stop and preserve evidence | C43: Do not accept automatic repair. Keep the file and contact the maintainer to restore a verified backup under the normal locks.
A44: Excel is open | B44: Save and close Excel | C44: Submitted decisions remain waiting. The service retries automatically when the workbook is available. Do not force a second writer.
A45: Unconfirmed submission | B45: Retry submission | C45: Use the existing request in the workbench so its request ID is preserved. For an outdated task, reload and review the current source version.
A46: Project documentation | B46: One entry point | C46: Start with the project-root README.md. Agent rules are in the root AGENTS.md; current System1 facts are in system1/PROJECT_STATE.md.

Sheet Categories
A1: Categories and Controlled Values
A2: Program-generated controlled values. Do not edit this sheet directly; update approved configuration and regenerate.
A4: Classification dimension | Source family and identifier prefix
A5: Code | B5: Option value | C5: Definition | D5: Folder code
A6: PA | B6: Public authority | C6: Government, regulator or permitting authority | D6: A_Public_Authority
A7: SB | B7: Standards body | C7: Standards organisation such as NS, EN or ISO | D7: B_Standards_Body
A8: CS | B8: Certification scheme | C8: Certification scheme such as ASC or GLOBALG.A.P. | D8: C_Certification_Scheme
A9: MS | B9: Manufacturer / supplier | C9: Equipment manufacturer or supplier | D9: D_Manufacturer_Supplier
A10: PE | B10: Project / engineering | C10: Site, design or engineering source | D10: E_Project_Engineering
A11: CI | B11: Client / internal | C11: Client, contract or internal rule | D11: F_Client_Internal
A12: PC | B12: Pending classification | C12: Temporary category; cannot be directly included | D12: Z_Pending_Classification
A14: Classification dimension | Document type
A15: Code | B15: Option value | C15: Definition | D15: Notes
A16: LAW | B16: Law | C16: Primary legislation
A17: REG | B17: Regulation | C17: Secondary legislation or regulation
A18: PER | B18: Permit / authority decision | C18: Permit or site-specific administrative decision
A19: STD | B19: Technical standard | C19: NS, EN, ISO or industry technical standard
A20: SCH | B20: Scheme standard | C20: Primary certification scheme standard
A21: INT | B21: Interpretation document | C21: Interpretation manual or guidance
A22: AUD | B22: Audit / assessment document | C22: Audit manual, checklist or assessment tool
A23: MAN | B23: Equipment manual / OEM instruction | C23: Manufacturer installation, operation, maintenance or safety instruction
A24: ENG | B24: Design / engineering document | C24: Design basis, analysis or engineering report
A25: CON | B25: Internal policy / contract | C25: Client, contract or internal normative document
A26: OTH | B26: Other | C26: Use only when no controlled document type applies
A28: Classification dimension | Requirement role
A29: Code | B29: Option value | C29: Definition | D29: Notes
A30: PN | B30: Primary normative | C30: Directly creates requirements within the approved scope
A31: RN | B31: Referenced normative | C31: Applies through citation by law, contract or a primary source
A32: AN | B32: Asset-specific normative | C32: Creates requirements only for confirmed applicable equipment, model, asset or configuration
A33: GI | B33: Guidance / interpretation | C33: Helps interpretation but does not independently create requirements
A34: AT | B34: Audit / assessment tool | C34: Supports verification and should link to a primary source
A35: CE | B35: Context / evidence | C35: Provides facts or proof; only normative statements may become requirements
A36: DW | B36: Draft working material | C36: Working material that cannot be treated as formal authority
A38: Authoritative language
A39: Code | B39: Option value | C39: Definition | D39: Notes
A40: EN | B40: English | C40: English is authoritative | D40: Use the authoritative language first; among equivalent official versions the working preference is English, then Norwegian, then Other
A41: NO | B41: Norwegian | C41: Norwegian is authoritative
A42: OT | B42: Other | C42: Another language is authoritative; specify details in notes
A44: Jurisdiction
A45: Code | B45: Option value | C45: Definition | D45: Notes
...

Sheet Source Register
A1: PROGRAM-MANAGED | DO NOT EDIT DIRECTLY | P1: HUMAN-GOVERNED | CHANGES APPLIED FROM HUMAN OPERATION DESKTOP
A2: source_id | B2: snapshot_id | C2: stored_filename | D2: snapshot_status | E2: selection_status | F2: download_status | G2: last_attempt_at | H2: last_success_at | I2: content_change | J2: current_origin | K2: current_snapshot_date | L2: failure_stage | M2: failure_reason | N2: needs_human_action | O2: content_hash | P2: source_title | Q2: official_url | R2: retrieval_url | S2: folder_code | T2: file_format | U2: issuer | V2: jurisdiction | W2: authoritative_language | X2: version | Y2: effective_date | Z2: source_family | AA2: document_type | AB2: requirement_role | AC2: inclusion_rationale | AD2: authority_quality | AE2: scope_relevance | AF2: version_currency | AG2: traceability | AH2: access_permission | AI2: automation_readiness | AJ2: operator_selection_decision | AK2: manual_update_date | AL2: manual_updated_by | AM2: source_status | AN2: primary_source_id | AO2: notes | AP2: acquisition_channel | AQ2: provenance_status | AR2: update_model | AS2: applicability_reference
A3: CS901 | B3: CS901-001 | C3: CS901-001_Synthetic.pdf | D3: STORED | E3: =IF(A3="","",IF(OR(AJ3="EXCLUDE",COUNTIF(AD3:AH3,"LOW")>0),"EXCLUDE",IF(OR(AJ3<>"INCLUDE",F3<>"SUCCESS",D3<>"STORED",U3="",AP3="",AQ3="",AQ3="UNVERIFIED",AND(AP3="OFFICIAL_WEBSITE",Q3=""),AND(OR(AA3="Equipment manual / OEM instruction",AB3="Asset-specific normative"),OR(Z3<>"Manufacturer / supplier",AS3="",AC3=""))),"PENDING",IF(COUNTIF(AD3:AH3,"HIGH")=5,"INCLUDE","PENDING")))) -> INCLUDE | F3: SUCCESS | I3: UNKNOWN | J3: NONE | K3: =IF(A3="","",IF(J3="AUTO",H3,IF(J3="MANUAL",AK3,""))) | L3: NONE | N3: =IF(A3="","",IF(COUNTIFS('Human Operation Desktop'!$A$3:$A$502,A3,'Human Operation Desktop'!$I$3:$I$502,"<>APPLIED",'Human Operation Desktop'!$I$3:$I$502,"<>REJECTED")>0,"YES","NO")) -> NO | P3: Synthetic test source 1 | Q3: https://example.invalid/source | R3: https://example.invalid/source | S3: C_Certification_Scheme | T3: pdf | U3: Test issuer | V3: Test jurisdiction | W3: English | Z3: Test source | AA3: Test document | AB3: Primary normative | AD3: HIGH | AE3: HIGH | AF3: HIGH | AG3: HIGH | AH3: HIGH | AJ3: INCLUDE | AM3: CURRENT | AP3: OFFICIAL_WEBSITE | AQ3: OFFICIAL_ORIGINAL | AR3: VERSIONED
A4: CS902 | B4: CS902-001 | C4: CS902-001_Synthetic.pdf | D4: NOT_COLLECTED | E4: =IF(A4="","",IF(OR(AJ4="EXCLUDE",COUNTIF(AD4:AH4,"LOW")>0),"EXCLUDE",IF(OR(AJ4<>"INCLUDE",F4<>"SUCCESS",D4<>"STORED",U4="",AP4="",AQ4="",AQ4="UNVERIFIED",AND(AP4="OFFICIAL_WEBSITE",Q4=""),AND(OR(AA4="Equipment manual / OEM instruction",AB4="Asset-specific normative"),OR(Z4<>"Manufacturer / supplier",AS4="",AC4=""))),"PENDING",IF(COUNTIF(AD4:AH4,"HIGH")=5,"INCLUDE","PENDING")))) -> PENDING | F4: NOT_RUN | I4: UNKNOWN | J4: NONE | K4: =IF(A4="","",IF(J4="AUTO",H4,IF(J4="MANUAL",AK4,""))) | L4: NONE | N4: =IF(A4="","",IF(COUNTIFS('Human Operation Desktop'!$A$3:$A$502,A4,'Human Operation Desktop'!$I$3:$I$502,"<>APPLIED",'Human Operation Desktop'!$I$3:$I$502,"<>REJECTED")>0,"YES","NO")) -> NO | P4: Synthetic test source 2 | Q4: https://example.invalid/source | R4: https://example.invalid/source | S4: C_Certification_Scheme | T4: pdf | U4: Test issuer | V4: Test jurisdiction | W4: English | Z4: Test source | AA4: Test document | AB4: Primary normative | AD4: HIGH | AE4: HIGH | AF4: HIGH | AG4: HIGH | AH4: HIGH | AJ4: PENDING | AM4: CURRENT | AP4: OFFICIAL_WEBSITE | AQ4: OFFICIAL_ORIGINAL | AR4: VERSIONED
E5: =IF(A5="","",IF(OR(AJ5="EXCLUDE",COUNTIF(AD5:AH5,"LOW")>0),"EXCLUDE",IF(OR(AJ5<>"INCLUDE",F5<>"SUCCESS",D5<>"STORED",U5="",AP5="",AQ5="",AQ5="UNVERIFIED",AND(AP5="OFFICIAL_WEBSITE",Q5=""),AND(OR(AA5="Equipment manual / OEM instruction",AB5="Asset-specific normative"),OR(Z5<>"Manufacturer / supplier",AS5="",AC5=""))),"PENDING",IF(COUNTIF(AD5:AH5,"HIGH")=5,"INCLUDE","PENDING")))) | K5: =IF(A5="","",IF(J5="AUTO",H5,IF(J5="MANUAL",AK5,""))) | N5: =IF(A5="","",IF(COUNTIFS('Human Operation Desktop'!$A$3:$A$502,A5,'Human Operation Desktop'!$I$3:$I$502,"<>APPLIED",'Human Operation Desktop'!$I$3:$I$502,"<>REJECTED")>0,"YES","NO"))
E6: =IF(A6="","",IF(OR(AJ6="EXCLUDE",COUNTIF(AD6:AH6,"LOW")>0),"EXCLUDE",IF(OR(AJ6<>"INCLUDE",F6<>"SUCCESS",D6<>"STORED",U6="",AP6="",AQ6="",AQ6="UNVERIFIED",AND(AP6="OFFICIAL_WEBSITE",Q6=""),AND(OR(AA6="Equipment manual / OEM instruction",AB6="Asset-specific normative"),OR(Z6<>"Manufacturer / supplier",AS6="",AC6=""))),"PENDING",IF(COUNTIF(AD6:AH6,"HIGH")=5,"INCLUDE","PENDING")))) | K6: =IF(A6="","",IF(J6="AUTO",H6,IF(J6="MANUAL",AK6,""))) | N6: =IF(A6="","",IF(COUNTIFS('Human Operation Desktop'!$A$3:$A$502,A6,'Human Operation Desktop'!$I$3:$I$502,"<>APPLIED",'Human Operation Desktop'!$I$3:$I$502,"<>REJECTED")>0,"YES","NO"))
E7: =IF(A7="","",IF(OR(AJ7="EXCLUDE",COUNTIF(AD7:AH7,"LOW")>0),"EXCLUDE",IF(OR(AJ7<>"INCLUDE",F7<>"SUCCESS",D7<>"STORED",U7="",AP7="",AQ7="",AQ7="UNVERIFIED",AND(AP7="OFFICIAL_WEBSITE",Q7=""),AND(OR(AA7="Equipment manual / OEM instruction",AB7="Asset-specific normative"),OR(Z7<>"Manufacturer / supplier",AS7="",AC7=""))),"PENDING",IF(COUNTIF(AD7:AH7,"HIGH")=5,"INCLUDE","PENDING")))) | K7: =IF(A7="","",IF(J7="AUTO",H7,IF(J7="MANUAL",AK7,""))) | N7: =IF(A7="","",IF(COUNTIFS('Human Operation Desktop'!$A$3:$A$502,A7,'Human Operation Desktop'!$I$3:$I$502,"<>APPLIED",'Human Operation Desktop'!$I$3:$I$502,"<>REJECTED")>0,"YES","NO"))
E8: =IF(A8="","",IF(OR(AJ8="EXCLUDE",COUNTIF(AD8:AH8,"LOW")>0),"EXCLUDE",IF(OR(AJ8<>"INCLUDE",F8<>"SUCCESS",D8<>"STORED",U8="",AP8="",AQ8="",AQ8="UNVERIFIED",AND(AP8="OFFICIAL_WEBSITE",Q8=""),AND(OR(AA8="Equipment manual / OEM instruction",AB8="Asset-specific normative"),OR(Z8<>"Manufacturer / supplier",AS8="",AC8=""))),"PENDING",IF(COUNTIF(AD8:AH8,"HIGH")=5,"INCLUDE","PENDING")))) | K8: =IF(A8="","",IF(J8="AUTO",H8,IF(J8="MANUAL",AK8,""))) | N8: =IF(A8="","",IF(COUNTIFS('Human Operation Desktop'!$A$3:$A$502,A8,'Human Operation Desktop'!$I$3:$I$502,"<>APPLIED",'Human Operation Desktop'!$I$3:$I$502,"<>REJECTED")>0,"YES","NO"))
E9: =IF(A9="","",IF(OR(AJ9="EXCLUDE",COUNTIF(AD9:AH9,"LOW")>0),"EXCLUDE",IF(OR(AJ9<>"INCLUDE",F9<>"SUCCESS",D9<>"STORED",U9="",AP9="",AQ9="",AQ9="UNVERIFIED",AND(AP9="OFFICIAL_WEBSITE",Q9=""),AND(OR(AA9="Equipment manual / OEM instruction",AB9="Asset-specific normative"),OR(Z9<>"Manufacturer / supplier",AS9="",AC9=""))),"PENDING",IF(COUNTIF(AD9:AH9,"HIGH")=5,"INCLUDE","PENDING")))) | K9: =IF(A9="","",IF(J9="AUTO",H9,IF(J9="MANUAL",AK9,""))) | N9: =IF(A9="","",IF(COUNTIFS('Human Operation Desktop'!$A$3:$A$502,A9,'Human Operation Desktop'!$I$3:$I$502,"<>APPLIED",'Human Operation Desktop'!$I$3:$I$502,"<>REJECTED")>0,"YES","NO"))
E10: =IF(A10="","",IF(OR(AJ10="EXCLUDE",COUNTIF(AD10:AH10,"LOW")>0),"EXCLUDE",IF(OR(AJ10<>"INCLUDE",F10<>"SUCCESS",D10<>"STORED",U10="",AP10="",AQ10="",AQ10="UNVERIFIED",AND(AP10="OFFICIAL_WEBSITE",Q10=""),AND(OR(AA10="Equipment manual / OEM instruction",AB10="Asset-specific normative"),OR(Z10<>"Manufacturer / supplier",AS10="",AC10=""))),"PENDING",IF(COUNTIF(AD10:AH10,"HIGH")=5,"INCLUDE","PENDING")))) | K10: =IF(A10="","",IF(J10="AUTO",H10,IF(J10="MANUAL",AK10,""))) | N10: =IF(A10="","",IF(COUNTIFS('Human Operation Desktop'!$A$3:$A$502,A10,'Human Operation Desktop'!$I$3:$I$502,"<>APPLIED",'Human Operation Desktop'!$I$3:$I$502,"<>REJECTED")>0,"YES","NO"))
E11: =IF(A11="","",IF(OR(AJ11="EXCLUDE",COUNTIF(AD11:AH11,"LOW")>0),"EXCLUDE",IF(OR(AJ11<>"INCLUDE",F11<>"SUCCESS",D11<>"STORED",U11="",AP11="",AQ11="",AQ11="UNVERIFIED",AND(AP11="OFFICIAL_WEBSITE",Q11=""),AND(OR(AA11="Equipment manual / OEM instruction",AB11="Asset-specific normative"),OR(Z11<>"Manufacturer / supplier",AS11="",AC11=""))),"PENDING",IF(COUNTIF(AD11:AH11,"HIGH")=5,"INCLUDE","PENDING")))) | K11: =IF(A11="","",IF(J11="AUTO",H11,IF(J11="MANUAL",AK11,""))) | N11: =IF(A11="","",IF(COUNTIFS('Human Operation Desktop'!$A$3:$A$502,A11,'Human Operation Desktop'!$I$3:$I$502,"<>APPLIED",'Human Operation Desktop'!$I$3:$I$502,"<>REJECTED")>0,"YES","NO"))
E12: =IF(A12="","",IF(OR(AJ12="EXCLUDE",COUNTIF(AD12:AH12,"LOW")>0),"EXCLUDE",IF(OR(AJ12<>"INCLUDE",F12<>"SUCCESS",D12<>"STORED",U12="",AP12="",AQ12="",AQ12="UNVERIFIED",AND(AP12="OFFICIAL_WEBSITE",Q12=""),AND(OR(AA12="Equipment manual / OEM instruction",AB12="Asset-specific normative"),OR(Z12<>"Manufacturer / supplier",AS12="",AC12=""))),"PENDING",IF(COUNTIF(AD12:AH12,"HIGH")=5,"INCLUDE","PENDING")))) | K12: =IF(A12="","",IF(J12="AUTO",H12,IF(J12="MANUAL",AK12,""))) | N12: =IF(A12="","",IF(COUNTIFS('Human Operation Desktop'!$A$3:$A$502,A12,'Human Operation Desktop'!$I$3:$I$502,"<>APPLIED",'Human Operation Desktop'!$I$3:$I$502,"<>REJECTED")>0,"YES","NO"))
E13: =IF(A13="","",IF(OR(AJ13="EXCLUDE",COUNTIF(AD13:AH13,"LOW")>0),"EXCLUDE",IF(OR(AJ13<>"INCLUDE",F13<>"SUCCESS",D13<>"STORED",U13="",AP13="",AQ13="",AQ13="UNVERIFIED",AND(AP13="OFFICIAL_WEBSITE",Q13=""),AND(OR(AA13="Equipment manual / OEM instruction",AB13="Asset-specific normative"),OR(Z13<>"Manufacturer / supplier",AS13="",AC13=""))),"PENDING",IF(COUNTIF(AD13:AH13,"HIGH")=5,"INCLUDE","PENDING")))) | K13: =IF(A13="","",IF(J13="AUTO",H13,IF(J13="MANUAL",AK13,""))) | N13: =IF(A13="","",IF(COUNTIFS('Human Operation Desktop'!$A$3:$A$502,A13,'Human Operation Desktop'!$I$3:$I$502,"<>APPLIED",'Human Operation Desktop'!$I$3:$I$502,"<>REJECTED")>0,"YES","NO"))
E14: =IF(A14="","",IF(OR(AJ14="EXCLUDE",COUNTIF(AD14:AH14,"LOW")>0),"EXCLUDE",IF(OR(AJ14<>"INCLUDE",F14<>"SUCCESS",D14<>"STORED",U14="",AP14="",AQ14="",AQ14="UNVERIFIED",AND(AP14="OFFICIAL_WEBSITE",Q14=""),AND(OR(AA14="Equipment manual / OEM instruction",AB14="Asset-specific normative"),OR(Z14<>"Manufacturer / supplier",AS14="",AC14=""))),"PENDING",IF(COUNTIF(AD14:AH14,"HIGH")=5,"INCLUDE","PENDING")))) | K14: =IF(A14="","",IF(J14="AUTO",H14,IF(J14="MANUAL",AK14,""))) | N14: =IF(A14="","",IF(COUNTIFS('Human Operation Desktop'!$A$3:$A$502,A14,'Human Operation Desktop'!$I$3:$I$502,"<>APPLIED",'Human Operation Desktop'!$I$3:$I$502,"<>REJECTED")>0,"YES","NO"))
E15: =IF(A15="","",IF(OR(AJ15="EXCLUDE",COUNTIF(AD15:AH15,"LOW")>0),"EXCLUDE",IF(OR(AJ15<>"INCLUDE",F15<>"SUCCESS",D15<>"STORED",U15="",AP15="",AQ15="",AQ15="UNVERIFIED",AND(AP15="OFFICIAL_WEBSITE",Q15=""),AND(OR(AA15="Equipment manual / OEM instruction",AB15="Asset-specific normative"),OR(Z15<>"Manufacturer / supplier",AS15="",AC15=""))),"PENDING",IF(COUNTIF(AD15:AH15,"HIGH")=5,"INCLUDE","PENDING")))) | K15: =IF(A15="","",IF(J15="AUTO",H15,IF(J15="MANUAL",AK15,""))) | N15: =IF(A15="","",IF(COUNTIFS('Human Operation Desktop'!$A$3:$A$502,A15,'Human Operation Desktop'!$I$3:$I$502,"<>APPLIED",'Human Operation Desktop'!$I$3:$I$502,"<>REJECTED")>0,"YES","NO"))
E16: =IF(A16="","",IF(OR(AJ16="EXCLUDE",COUNTIF(AD16:AH16,"LOW")>0),"EXCLUDE",IF(OR(AJ16<>"INCLUDE",F16<>"SUCCESS",D16<>"STORED",U16="",AP16="",AQ16="",AQ16="UNVERIFIED",AND(AP16="OFFICIAL_WEBSITE",Q16=""),AND(OR(AA16="Equipment manual / OEM instruction",AB16="Asset-specific normative"),OR(Z16<>"Manufacturer / supplier",AS16="",AC16=""))),"PENDING",IF(COUNTIF(AD16:AH16,"HIGH")=5,"INCLUDE","PENDING")))) | K16: =IF(A16="","",IF(J16="AUTO",H16,IF(J16="MANUAL",AK16,""))) | N16: =IF(A16="","",IF(COUNTIFS('Human Operation Desktop'!$A$3:$A$502,A16,'Human Operation Desktop'!$I$3:$I$502,"<>APPLIED",'Human Operation Desktop'!$I$3:$I$502,"<>REJECTED")>0,"YES","NO"))
... E302: =IF(A302="","",IF(OR(AJ302="EXCLUDE",COUNTIF(AD302:AH302,"LOW")>0),"EXCLUDE",IF(OR(AJ302<>"INCLUDE",F302<>"SUCCESS",D302<>"STORED",U302="",AP302="",AQ302="",AQ302="UNVERIFIED",AND(AP302="OFFICIAL_WEBSITE",Q302=""),AND(OR(AA302="Equipment manual / OEM instruction",AB302="Asset-specific normative"),OR(Z302<>"Manufacturer / supplier",AS302="",AC302=""))),"PENDING",IF(COUNTIF(AD302:AH302,"HIGH")=5,"INCLUDE","PENDING")))) | K302: =IF(A302="","",IF(J302="AUTO",H302,IF(J302="MANUAL",AK302,""))) | N302: =IF(A302="","",IF(COUNTIFS('Human Operation Desktop'!$A$3:$A$502,A302,'Human Operation Desktop'!$I$3:$I$502,"<>APPLIED",'Human Operation Desktop'!$I$3:$I$502,"<>REJECTED")>0,"YES","NO"))

Sheet Dashboard
A1: SYSTEM1 SOURCE MANAGEMENT | I1: LAST DATA UPDATE | M1: AUTOMATION | R1: Primary category | S1: Total | T1: Included | U1: Folder code
A2: Read-only management overview. Complete all decisions in Human Operation Desktop. | I2: =MAX(MAX(SourceRegisterTable[last_attempt_at]),MAX(HumanOperationsTable[program_operated_at])) -> 0 | M2: USER CONFIGURED | R2: Public authority | S2: =COUNTIF(SourceRegisterTable[folder_code],U2) -> 0 | T2: =COUNTIFS(SourceRegisterTable[folder_code],U2,SourceRegisterTable[selection_status],"INCLUDE") -> 0 | U2: A_Public_Authority
R3: Standards body | S3: =COUNTIF(SourceRegisterTable[folder_code],U3) -> 0 | T3: =COUNTIFS(SourceRegisterTable[folder_code],U3,SourceRegisterTable[selection_status],"INCLUDE") -> 0 | U3: B_Standards_Body
A4: TOTAL SOURCES | C4: INCLUDED SOURCES | E4: STORED SNAPSHOTS | H4: OPEN HUMAN TASKS | L4: RETRIEVAL EXCEPTIONS | R4: Certification scheme | S4: =COUNTIF(SourceRegisterTable[folder_code],U4) -> 2 | T4: =COUNTIFS(SourceRegisterTable[folder_code],U4,SourceRegisterTable[selection_status],"INCLUDE") -> 1 | U4: C_Certification_Scheme
A5: =COUNTA(SourceRegisterTable[source_id]) -> 2 | C5: =COUNTIF(SourceRegisterTable[selection_status],"INCLUDE") -> 1 | E5: =COUNTIF(SourceRegisterTable[snapshot_status],"STORED") -> 1 | H5: =COUNTIF(HumanOperationsTable[program_status],"PENDING")+COUNTIF(HumanOperationsTable[program_status],"WAITING_FOR_HUMAN")+COUNTIF(HumanOperationsTable[program_status],"NEEDS_REPLAN") -> 0 | L5: =COUNTIF(SourceRegisterTable[download_status],"FAIL")+COUNTIF(SourceRegisterTable[download_status],"PAYWALL_BLOCKED") -> 0 | R5: Manufacturer / supplier | S5: =COUNTIF(SourceRegisterTable[folder_code],U5) -> 0 | T5: =COUNTIFS(SourceRegisterTable[folder_code],U5,SourceRegisterTable[selection_status],"INCLUDE") -> 0 | U5: D_Manufacturer_Supplier
R6: Project / engineering | S6: =COUNTIF(SourceRegisterTable[folder_code],U6) -> 0 | T6: =COUNTIFS(SourceRegisterTable[folder_code],U6,SourceRegisterTable[selection_status],"INCLUDE") -> 0 | U6: E_Project_Engineering
A7: Registered sources | C7: =TEXT(C5/A5,"0%")&" of total" -> 50% of total | E7: =TEXT(E5/A5,"0%")&" collection rate" -> 50% collection rate | H7: ="Oldest: "&S17&" days" -> Oldest: 0 days | L7: FAIL + PAYWALL_BLOCKED | R7: Client internal | S7: =COUNTIF(SourceRegisterTable[folder_code],U7) -> 0 | T7: =COUNTIFS(SourceRegisterTable[folder_code],U7,SourceRegisterTable[selection_status],"INCLUDE") -> 0 | U7: F_Client_Internal
R8: Pending classification | S8: =COUNTIF(SourceRegisterTable[folder_code],U8) -> 0 | T8: =COUNTIFS(SourceRegisterTable[folder_code],U8,SourceRegisterTable[selection_status],"INCLUDE") -> 0 | U8: Z_Pending_Classification
A9: =IF(H5=0,"All human operations are clear.",IF(S17>60,"Human review is overdue. Open Human Operation Desktop and address the oldest items.","Human review is pending. Open Human Operation Desktop to review the current queue.")) -> All human operations are clear.
R10: Selection status | S10: Count | T10: Share
R11: INCLUDE | S11: =COUNTIF(SourceRegisterTable[selection_status],R11) -> 1 | T11: =IFERROR(S11/SUM($S$11:$S$13),0) -> 0.5
A12: SOURCE PORTFOLIO | K12: SELECTION STATUS | R12: PENDING | S12: =COUNTIF(SourceRegisterTable[selection_status],R12) -> 1 | T12: =IFERROR(S12/SUM($S$11:$S$13),0) -> 0.5
R13: EXCLUDE | S13: =COUNTIF(SourceRegisterTable[selection_status],R13) -> 0 | T13: =IFERROR(S13/SUM($S$11:$S$13),0) -> 0
R15: Program status | S15: Oldest days
R16: OPEN TASKS | S16: =H5 -> 0
R17: OLDEST OPEN | S17: =MAX(T30:T130) -> 0
R19: Retrieval status | S19: Count | T19: Share
R20: SUCCESS | S20: =COUNTIF(SourceRegisterTable[download_status],R20) -> 1 | T20: =IFERROR(S20/A5,0) -> 0.5
R21: NOT_RUN | S21: =COUNTIF(SourceRegisterTable[download_status],R21) -> 1 | T21: =IFERROR(S21/A5,0) -> 0.5
K22: INCLUDE | M22: PENDING | O22: EXCLUDE | R22: PAYWALL_BLOCKED | S22: =COUNTIF(SourceRegisterTable[download_status],R22) -> 0 | T22: =IFERROR(S22/A5,0) -> 0
K23: =S11&" | "&TEXT(T11,"0%") -> 1 | 50% | M23: =S12&" | "&TEXT(T12,"0%") -> 1 | 50% | O23: =S13&" | "&TEXT(T13,"0%") -> 0 | 0% | R23: FAIL | S23: =COUNTIF(SourceRegisterTable[download_status],R23) -> 0 | T23: =IFERROR(S23/A5,0) -> 0
A26: RETRIEVAL HEALTH | I26: GOVERNANCE & QA
A27: STATUS | D27: COUNT | G27: SHARE | I27: LAST QA CHECK | M27: =MAX(_xlfn.MAXIFS(HumanOperationsTable[checked_at],HumanOperationsTable[task_type],"RANDOM_QA_CHECK"),_xlfn.MAXIFS(HumanOperationsTable[checked_at],HumanOperationsTable[task_type],"RANDOM_QA_BATCH_SUMMARY")) -> 0
A28: =R20 -> SUCCESS | D28: =S20 -> 1 | G28: =T20 -> 0.5 | I28: CORRECT / CHECKED | M28: =(7+COUNTIFS(HumanOperationsTable[task_type],"RANDOM_QA_CHECK",HumanOperationsTable[operator_action],"CORRECT"))&" / "&(7+COUNTIFS(HumanOperationsTable[task_type],"RANDOM_QA_CHECK",HumanOperationsTable[operator_action],"<>PENDING")) -> 7 / 7
A29: =R21 -> NOT_RUN | D29: =S21 -> 1 | G29: =T21 -> 0.5 | I29: ACCURACY | M29: =IFERROR((7+COUNTIFS(HumanOperationsTable[task_type],"RANDOM_QA_CHECK",HumanOperationsTable[operator_action],"CORRECT"))/(7+COUNTIFS(HumanOperationsTable[task_type],"RANDOM_QA_CHECK",HumanOperationsTable[operator_action],"<>PENDING")),0) -> 1
A30: =R22 -> PAYWALL_BLOCKED | D30: =S22 -> 0 | G30: =T22 -> 0 | I30: OPEN QA | M30: =COUNTIFS(HumanOperationsTable[task_type],"RANDOM_QA_CHECK",HumanOperationsTable[program_status],"PENDING")+COUNTIFS(HumanOperationsTable[task_type],"RANDOM_QA_CHECK",HumanOperationsTable[program_status],"WAITING_FOR_HUMAN")+COUNTIFS(HumanOperationsTable[task_type],"RANDOM_QA_CHECK",HumanOperationsTable[program_status],"NEEDS_REPLAN") -> 0 | R30: ='Human Operation Desktop'!I3 -> 0 | S30: ='Human Operation Desktop'!AQ3 -> 0 | T30: =IF(AND(S30>0,OR(R30="PENDING",R30="WAITING_FOR_HUMAN",R30="NEEDS_REPLAN")),MAX(0,INT(TODAY()-S30)),0) -> 0
A31: =R23 -> FAIL | D31: =S23 -> 0 | G31: =T23 -> 0 | I31: SOURCE REVIEW | M31: =COUNTIFS(HumanOperationsTable[task_type],"SOURCE_REVIEW",HumanOperationsTable[program_status],"PENDING")+COUNTIFS(HumanOperationsTable[task_type],"SOURCE_REVIEW",HumanOperationsTable[program_status],"WAITING_FOR_HUMAN")+COUNTIFS(HumanOperationsTable[task_type],"SOURCE_REVIEW",HumanOperationsTable[program_status],"NEEDS_REPLAN") -> 0 | R31: ='Human Operation Desktop'!I4 -> 0 | S31: ='Human Operation Desktop'!AQ4 -> 0 | T31: =IF(AND(S31>0,OR(R31="PENDING",R31="WAITING_FOR_HUMAN",R31="NEEDS_REPLAN")),MAX(0,INT(TODAY()-S31)),0) -> 0
I32: SELECTION REVIEW | M32: =COUNTIFS(HumanOperationsTable[task_type],"SELECTION_REVIEW",HumanOperationsTable[program_status],"PENDING")+COUNTIFS(HumanOperationsTable[task_type],"SELECTION_REVIEW",HumanOperationsTable[program_status],"WAITING_FOR_HUMAN")+COUNTIFS(HumanOperationsTable[task_type],"SELECTION_REVIEW",HumanOperationsTable[program_status],"NEEDS_REPLAN") -> 0 | R32: ='Human Operation Desktop'!I5 -> 0 | S32: ='Human Operation Desktop'!AQ5 -> 0 | T32: =IF(AND(S32>0,OR(R32="PENDING",R32="WAITING_FOR_HUMAN",R32="NEEDS_REPLAN")),MAX(0,INT(TODAY()-S32)),0) -> 0
R33: ='Human Operation Desktop'!I6 -> 0 | S33: ='Human Operation Desktop'!AQ6 -> 0 | T33: =IF(AND(S33>0,OR(R33="PENDING",R33="WAITING_FOR_HUMAN",R33="NEEDS_REPLAN")),MAX(0,INT(TODAY()-S33)),0) -> 0
R34: ='Human Operation Desktop'!I7 -> 0 | S34: ='Human Operation Desktop'!AQ7 -> 0 | T34: =IF(AND(S34>0,OR(R34="PENDING",R34="WAITING_FOR_HUMAN",R34="NEEDS_REPLAN")),MAX(0,INT(TODAY()-S34)),0) -> 0
A35: SOURCE ID | B35: SOURCE TITLE | C35: TASK TYPE | D35: ISSUE SUMMARY | E35: DAYS OPEN | F35: PROGRAM STATUS | G35: PRIORITY ITEMS | TOP 5 | R35: ='Human Operation Desktop'!I8 -> 0 | S35: ='Human Operation Desktop'!AQ8 -> 0 | T35: =IF(AND(S35>0,OR(R35="PENDING",R35="WAITING_FOR_HUMAN",R35="NEEDS_REPLAN")),MAX(0,INT(TODAY()-S35)),0) -> 0
A36: SB001 | B36: NS 9415:2021+AC:2024 Floating aquaculture farms - Site survey, design, execution and use | C36: SOURCE_REVIEW | D36: PAYWALL_BLOCKED; SELECTION_PENDING | E36: 15 | F36: PENDING | R36: ='Human Operation Desktop'!I9 -> 0 | S36: ='Human Operation Desktop'!AQ9 -> 0 | T36: =IF(AND(S36>0,OR(R36="PENDING",R36="WAITING_FOR_HUMAN",R36="NEEDS_REPLAN")),MAX(0,INT(TODAY()-S36)),0) -> 0
A37: SB002 | B37: NS 9410:2016 Environmental monitoring of benthic impact from marine fish farms | C37: SOURCE_REVIEW | D37: PAYWALL_BLOCKED; SELECTION_PENDING | E37: 15 | F37: PENDING | R37: ='Human Operation Desktop'!I10 -> 0 | S37: ='Human Operation Desktop'!AQ10 -> 0 | T37: =IF(AND(S37>0,OR(R37="PENDING",R37="WAITING_FOR_HUMAN",R37="NEEDS_REPLAN")),MAX(0,INT(TODAY()-S37)),0) -> 0
A38: SB003 | B38: NS 9416:2013 Land-based aquaculture facilities for fish | C38: SOURCE_REVIEW | D38: PAYWALL_BLOCKED; SELECTION_PENDING | E38: 15 | F38: PENDING | R38: ='Human Operation Desktop'!I11 -> 0 | S38: ='Human Operation Desktop'!AQ11 -> 0 | T38: =IF(AND(S38>0,OR(R38="PENDING",R38="WAITING_FOR_HUMAN",R38="NEEDS_REPLAN")),MAX(0,INT(TODAY()-S38)),0) -> 0
A39: SB004 | B39: NS 5814:2021+AC:2023 Requirements for risk assessments | C39: SOURCE_REVIEW | D39: PAYWALL_BLOCKED; SELECTION_PENDING | E39: 15 | F39: PENDING | R39: ='Human Operation Desktop'!I12 -> 0 | S39: ='Human Operation Desktop'!AQ12 -> 0 | T39: =IF(AND(S39>0,OR(R39="PENDING",R39="WAITING_FOR_HUMAN",R39="NEEDS_REPLAN")),MAX(0,INT(TODAY()-S39)),0) -> 0
A40: SB005 | B40: NS-ISO 31000:2018 Risk management - Guidelines | C40: SOURCE_REVIEW | D40: PAYWALL_BLOCKED; SELECTION_PENDING | E40: 15 | F40: PENDING | R40: ='Human Operation Desktop'!I13 -> 0 | S40: ='Human Operation Desktop'!AQ13 -> 0 | T40: =IF(AND(S40>0,OR(R40="PENDING",R40="WAITING_FOR_HUMAN",R40="NEEDS_REPLAN")),MAX(0,INT(TODAY()-S40)),0) -> 0
R41: ='Human Operation Desktop'!I14 -> 0 | S41: ='Human Operation Desktop'!AQ14 -> 0 | T41: =IF(AND(S41>0,OR(R41="PENDING",R41="WAITING_FOR_HUMAN",R41="NEEDS_REPLAN")),MAX(0,INT(TODAY()-S41)),0) -> 0
A42: Complete decisions in Human Operation Desktop, save and close Excel, then run Routine Cycle. | R42: ='Human Operation Desktop'!I15 -> 0 | S42: ='Human Operation Desktop'!AQ15 -> 0 | T42: =IF(AND(S42>0,OR(R42="PENDING",R42="WAITING_FOR_HUMAN",R42="NEEDS_REPLAN")),MAX(0,INT(TODAY()-S42)),0) -> 0
R43: ='Human Operation Desktop'!I16 -> 0 | S43: ='Human Operation Desktop'!AQ16 -> 0 | T43: =IF(AND(S43>0,OR(R43="PENDING",R43="WAITING_FOR_HUMAN",R43="NEEDS_REPLAN")),MAX(0,INT(TODAY()-S43)),0) -> 0
R44: ='Human Operation Desktop'!I17 -> 0 | S44: ='Human Operation Desktop'!AQ17 -> 0 | T44: =IF(AND(S44>0,OR(R44="PENDING",R44="WAITING_FOR_HUMAN",R44="NEEDS_REPLAN")),MAX(0,INT(TODAY()-S44)),0) -> 0
...

Sheet Human Operation Desktop
A1: OPERATOR WORK QUEUE | K1: SOURCE CORRECTIONS | UNHIDE ONLY WHEN REQUESTED | W1: CANDIDATE DETAILS | UNHIDE ONLY FOR NEW SOURCES | AN1: PROGRAM SUPPORT | DO NOT EDIT
A2: source_id | B2: source_title | C2: task_type | D2: issue_summary | E2: requested_action | F2: operator_action | G2: operator | H2: operator_note | I2: program_status | J2: program_result | K2: official_url | L2: retrieval_url | M2: authority_quality | N2: scope_relevance | O2: version_currency | P2: traceability | Q2: access_permission | R2: operator_selection_decision | S2: applicability_reference | T2: source_status | U2: primary_source_id | V2: source_notes | W2: intake_file | X2: folder_code | Y2: issuer | Z2: jurisdiction | AA2: document_type | AB2: source_family | AC2: requirement_role | AD2: authoritative_language | AE2: file_format | AF2: version | AG2: effective_date | AH2: inclusion_rationale | AI2: automation_readiness | AJ2: acquisition_channel | AK2: provenance_status | AL2: update_model | AM2: candidate_origin | AN2: operation_id | AO2: checked_at | AP2: program_operated_at | AQ2: created_at | AR2: payload_json

Sheet Machine confidence
A1: Source ID | B1: Authority Quality confidence | C1: Scope Relevance confidence | D1: Version Currency confidence | E1: Traceability confidence | F1: Access Permission confidence | G1: Calibration status | H1: Policy revision | I1: Threshold | J1: Source SHA256 | K1: Assessment ID | L1: Assessment method / evidence
