Workbook

Sheet Audit_Info
A1: This checklist is used for the audit checklist upload for the GLOBALG.A.P. database.
A2: (*) Mandatory entry | B2: Use multiple lines for "Key persons", "Auditors" and "Sites/PHUs".
A3: AuditID: | E3: IFA v6 Smart Aquaculture
A4: GGN*: | E4: Audited Company*:
A5: Reporting Option | B5: Please select
A6: Contact Person Name* | B6: Contact Person Surname* | C6: Email* | D6: Key persons present during the Audit, Name* | E6: Company* | F6: Position* | G6: Location of main site seen during the audit | H6: Company Profile (briefly describe company audited) | I6: Audit Date start* | J6: Audit Date end* | K6: General Notes on the audit | L6: Internal Notes on the audit | M6: Travel required between sites/PHUs (Y/N)?* | N6: Travel mode used | O6: Time (minutes) | P6: Travel Date | Q6: GAIN | R6: Auditor Name | S6: Sites audited | T6: Site audited Start Date/Time | U6: Site audited End Date/Time

Sheet Audit scope_Info
A1: Instructions
A2: The product registration in the GLOBALG.A.P. database is leading.
A5: Audit Details: IFA v6 Smart | B5: Audit type* -Initial certification audit -Audit for sites and members -Surveillance audit for sites and members -Subsequent audit -Recertification audit -Follow-up on-site audit -Modification audit | C5: Where is the audit conducted?* -On-site -On-Site + Off-Site -Off-site/Admin -Remote | D5: How is the audit conducted?* -Announced -Unannounced <48h -Unannounced 0 h -Randomly selected in case of option 2 members or site of an option 1 with QMS (GFS only) | E5: Does the audit take place in combination with any other standard or add-on? If so, indicate which standard or add-on.
B7: Sites Audited | C7: Site Type -SITE -PHU -EXTERNAL_PHU (Subcontracted) | D7: Site Name | E7: Site Address | F7: Site Coordinates
B9: GFSI recognized (post-farm) certification at the time of the inspection? * -Yes -No
B11: HACCP recognized (post-farm) certification at the time of the inspection? * -Yes -No
B13: Products | C13: Additional Data or Variety (optional) | D13: Broodstock additionally purchased? | E13: Seedlings (ova) additionally purchased? -Yes -No | F13: Seedlings (juvenile) additionally purchased? -Yes -No | G13: Feed supplied (internally or externally)? -Yes -No | H13: PO, Production of certified and non-certified products - Yes - No | I13: PO, Ownership/Purchase of certified and non-certified products - Yes - No | J13: Trade. Does the producer buy certified product from external sources - Yes - No | K13: No use of antimicrobials for the last certification cycle? -Yes -No | L13: Production system used for on-growing stage? - On/Off Bottom Cultures - Ponds and Tanks -Recirculating AQ Systems (RAS) -Net Pens -N/A (hatcheries) Other | M13: Countries of destination: one or multiple countries | N13: BroodstockInHouse | O13: Seedlings (ova) in-house, estimated organisms in no. | P13: Seedlings (juvenile) in-house, estimated organisms in no. | Q13: Farmed aquatic species, annual quantity in metric tonnes at point of harvest
B15: Products For PHUs | C15: Post harvest activity? -Yes -No | D15: PO, Production of certified and non-certified products - Yes - No | E15: PO, Ownership/Purchase of certified and non-certified products - Yes - No | F15: Trade. Does the producer buy certified product from external sources - Yes - No
B17: Products For external PHUs (Subcontracted) | C17: Post harvest activity? -Yes -No | D17: PO, Production of certified and non-certified products - Yes - No | E17: PO, Ownership/Purchase of certified and non-certified products - Yes - No | F17: Trade. Does the producer buy certified product from external sources - Yes - No
A20: Products and activities observed during the audit* | B20: Has product handling been observed during the audit? - Yes - No | C20: If yes, of which products? | D20: List all products presented during the audit: | E20: Does the producer buy products from certified production processes from external sources? | F20: If yes, which products? | G20: Has the harvest of the products been seen during this CB audit? | H20: If yes, list products

Sheet CL - IFA v6 Smart - AQ
A1: Disclaimer: Translation of normative documents: in case of doubt, the English version applies
A2: Instructions
B3: The correct values for the "Answers" column are: Text (Yes, No, N/A respectively)
B4: The "Justification" column is free text.
B5: The color of the cell reminds that this P&C cannot be answered with "Not Applicable".
B6: In case of principles and criteria are "N/A" all questions shall be put "N/A" and the relevant principles and criteria that can not be selected as "N/A" shall be put on "Yes"
B7: The "Due date" column is mandatory for the P&Cs with answer No and Major Must or Minor Must level.
A9: Standard | B9: Version | C9: Product Category | D9: Principle | E9: Section | F9: Description | G9: Criteria | H9: NIG | I9: Level | J9: Yes | K9: No | L9: N/A | M9: Answer Confirmation | N9: Method | O9: Inspection method | P9: Justification guide | Q9: Justification | R9: Due date | S9: Site 1 | T9: Site 2 | U9: Site 3 | V9: Site 4 | W9: Site 5 | X9: Site 6 | Y9: Site 7 | Z9: Site 8 | AA9: Site 9 | AB9: Site 10
A10: IFA | B10: IFA v6 Smart | C10: AQ | D10: AQ-Smart 01.01.01 | E10: AQ 01 SITE HISTORY AND SITE MANAGEMENT | F10: The producer has a reference system for identifying sites used in production, other areas, and facilities. | G10: Compliance shall require visual identification in the form of: a physical sign and a farm map which also identifies the location of water sources, storage/handling facilities, production units, entry and exit points, etc., and that can be cross-referenced to the identification system. No “N/A.” | I10: Major Must | M10: =IF(AND(J10<>"",ISBLANK(K10),ISBLANK(L10)),"Yes",IF(AND(K10<>"",ISBLANK(J10),ISBLANK(L10)),"No",IF(AND(L10<>"",ISBLANK(J10),ISBLANK(K10)),"N/A","not answered/error"))) -> not answered/error | Q10: Confirmation that a map is available and that it clearly identifies all sites. If physical signs are in place, this shall be recorded.
A11: IFA | B11: IFA v6 Smart | C11: AQ | D11: AQ-Smart 01.01.02 | E11: AQ 01 SITE HISTORY AND SITE MANAGEMENT | F11: A recording system is established for each production unit to provide a record of the production activities undertaken. | G11: Current records shall provide a history of GLOBALG.A.P. certified production at all production units. This shall be done either digitally or on paper. No “N/A.” | I11: Major Must | M11: =IF(AND(J11<>"",ISBLANK(K11),ISBLANK(L11)),"Yes",IF(AND(K11<>"",ISBLANK(J11),ISBLANK(L11)),"No",IF(AND(L11<>"",ISBLANK(J11),ISBLANK(K11)),"N/A","not answered/error"))) -> not answered/error | Q11: Identification of the site and the period where all history of activities were revised.
A12: IFA | B12: IFA v6 Smart | C12: AQ | D12: AQ-Smart 01.02.01 | E12: AQ 01 SITE HISTORY AND SITE MANAGEMENT | F12: A risk assessment is available for all sites registered for certification to evaluate whether the sites are suitable for continuing farming operations. | G12: A documented risk assessment to determine whether the sites (including rented land, structures, and equipment) are appropriate for production shall be available for all sites, considering aspects of food safety, the environment, and the health and welfare of farmed aquatic species. It shall be ready for the initial certification body (CB) audit and maintained, updated, and reviewed whenever new sites enter into production, when risks for existing ones have changed, or at least annually, whichever occurs first. The risk assessment may be based on a generic one but shall be customized to the farm situation. A list of all activities potentially affecting the aquaculture farm shall be available with regard to: potential physical, chemical (including allergens), and biological hazards. Cross-reference with AQ 20.02.16 and AQ 20.02.18. | I12: Major Must | M12: =IF(AND(J12<>"",ISBLANK(K12),ISBLANK(L12)),"Yes",IF(AND(K12<>"",ISBLANK(J12),ISBLANK(L12)),"No",IF(AND(L12<>"",ISBLANK(J12),ISBLANK(K12)),"N/A","not answered/error"))) -> not answered/error | Q12: A documented risk assessment is available with a list A list of all activities potentially affecting the aquaculture farm: potential physical, chemical (including allergens), and biological hazards. Document identification name: code: revision: date:
A13: IFA | B13: IFA v6 Smart | C13: AQ | D13: AQ-Smart 01.02.02 | E13: AQ 01 SITE HISTORY AND SITE MANAGEMENT | F13: A management plan that establishes strategies for minimizing the risks identified in the risk assessment for operation suitability has been developed and implemented and is reviewed regularly. | G13: A management plan shall address the risks identified in AQ 01.02.01 and describe the hazard control procedures that justify that the site in question is suitable for production, ensuring sustainability and effectiveness. This plan shall be appropriate to farm operations, and there shall be evidence of its implementation. The plan shall address maintenance of grounds and areas within the site to prevent contamination. The plan shall be reviewed annually, or whenever changes occur that may impact the safety of food production and impact the food safety plan, whichever occurs first. | I13: Major Must | M13: =IF(AND(J13<>"",ISBLANK(K13),ISBLANK(L13)),"Yes",IF(AND(K13<>"",ISBLANK(J13),ISBLANK(L13)),"No",IF(AND(L13<>"",ISBLANK(J13),ISBLANK(K13)),"N/A","not answered/error"))) -> not answered/error | Q13: A management pla address the risks identified in AQ 01.02.01. Document identification name: code: revision: date:
A14: IFA | B14: IFA v6 Smart | C14: AQ | D14: AQ-Smart 01.02.03 | E14: AQ 01 SITE HISTORY AND SITE MANAGEMENT | F14: All structures are located, designed, and constructed to facilitate proper cleaning and pest control. | G14: Where appropriate, the design and layout shall permit compliance with good hygiene practices, including protection against cross contamination between and during operations. This requirement shall include all adjoining rooms, equipment, facilities, and feeding systems. A program of self-assessments/internal audits shall be established, implemented, and maintained to ensure the sites and equipment are routinely maintained in a suitable condition to ensure food safety, as applicable to the activity of the site. Self-assessments/Internal audits can be at an interval determined by the producer in accordance with the assessed risk. | I14: Major Must | M14: =IF(AND(J14<>"",ISBLANK(K14),ISBLANK(L14)),"Yes",IF(AND(K14<>"",ISBLANK(J14),ISBLANK(L14)),"No",IF(AND(L14<>"",ISBLANK(J14),ISBLANK(K14)),"N/A","not answered/error"))) -> not answered/error
A15: IFA | B15: IFA v6 Smart | C15: AQ | D15: AQ-Smart 01.03.01 | E15: AQ 01 SITE HISTORY AND SITE MANAGEMENT | F15: Farm management is able to demonstrate awareness at interview of compliance with legislation. | G15: In the interview, farm management shall be able to demonstrate how it fulfills its legal obligations with respect to the food safety, farmed aquatic species health and welfare, feed formulation, environment, biodiversity, and workers’ health and safety legislation applicable to its enterprise. No “N/A.” | I15: Major Must | M15: =IF(AND(J15<>"",ISBLANK(K15),ISBLANK(L15)),"Yes",IF(AND(K15<>"",ISBLANK(J15),ISBLANK(L15)),"No",IF(AND(L15<>"",ISBLANK(J15),ISBLANK(K15)),"N/A","not answered/error"))) -> not answered/error
A16: IFA | B16: IFA v6 Smart | C16: AQ | D16: AQ-Smart 01.03.02 | E16: AQ 01 SITE HISTORY AND SITE MANAGEMENT | F16: Aquaculture farms are registered as such with the relevant competent authority as required by national legislation for the specific farmed aquatic species. | G16: Registration and license documents shall be available. Examples include: seabed leases and consents for discharge of effluent and licenses/concessions from authority to grow a set biomass of aquaculture products or allocation of feed quota. No “N/A.” | I16: Major Must | M16: =IF(AND(J16<>"",ISBLANK(K16),ISBLANK(L16)),"Yes",IF(AND(K16<>"",ISBLANK(J16),ISBLANK(L16)),"No",IF(AND(L16<>"",ISBLANK(J16),ISBLANK(K16)),"N/A","not answered/error"))) -> not answered/error | Q16: Document identification name/type of licence: code: revision: date: institution that issue the license: Date of validity of the license/permit.
A17: IFA | B17: IFA v6 Smart | C17: AQ | D17: AQ-Smart 02.01 | E17: AQ 02 INTERNAL DOCUMENTATION | F17: In the initial phase (initial certification body (CB) audit) of application of the standard, site records demonstrate compliance with the standard for the last three months. | G17: Records shall be in place for the last three months demonstrating compliance sufficient to achieve GLOBALG.A.P. certification. No “N/A.” | I17: Major Must | M17: =IF(AND(J17<>"",ISBLANK(K17),ISBLANK(L17)),"Yes",IF(AND(K17<>"",ISBLANK(J17),ISBLANK(L17)),"No",IF(AND(L17<>"",ISBLANK(J17),ISBLANK(K17)),"N/A","not answered/error"))) -> not answered/error | Q17: all records verified show as a minimum three months of recording. Example: XXXXXXXXXXX For consecutive audits, report: "Consecutive audit."
A18: IFA | B18: IFA v6 Smart | C18: AQ | D18: AQ-Smart 02.02 | E18: AQ 02 INTERNAL DOCUMENTATION | F18: A documented system with procedures and work instructions covering all processes is available and implemented. | G18: Documented procedures and work instructions shall be available on the site demonstrating compliance with food safety, legal, and standard requirements, including supplier approval procedures. No “N/A.” | I18: Major Must | M18: =IF(AND(J18<>"",ISBLANK(K18),ISBLANK(L18)),"Yes",IF(AND(K18<>"",ISBLANK(J18),ISBLANK(L18)),"No",IF(AND(L18<>"",ISBLANK(J18),ISBLANK(K18)),"N/A","not answered/error"))) -> not answered/error | Q18: Document identification name: code: revision: date:
A19: IFA | B19: IFA v6 Smart | C19: AQ | D19: AQ-Smart 02.03 | E19: AQ 02 INTERNAL DOCUMENTATION | F19: The aquaculture farm and the production units have an organizational structure with defined responsibilities. | G19: A clear organizational structure identifying the job functions and responsibilities shall be established, implemented, and maintained. Workers whose activities have a potential impact on food safety shall be identified. No “N/A.” | I19: Major Must | M19: =IF(AND(J19<>"",ISBLANK(K19),ISBLANK(L19)),"Yes",IF(AND(K19<>"",ISBLANK(J19),ISBLANK(L19)),"No",IF(AND(L19<>"",ISBLANK(J19),ISBLANK(K19)),"N/A","not answered/error"))) -> not answered/error | Q19: Document identification name: code: revision: date:
A20: IFA | B20: IFA v6 Smart | C20: AQ | D20: AQ-Smart 02.04 | E20: AQ 02 INTERNAL DOCUMENTATION | F20: Geographical coordinates identify all operations of the farm. | G20: Geographical coordinates shall identify all sites where the actual aquatic operation takes place. The coordinates shall refer to the center of the production site (smaller sites; <1 ha) or the corners of the contours of the production sites (larger sites; >1 ha). The coordinates (degrees and minutes of latitude and longitude) shall be within an accuracy of two decimals in the geographical minutes (e.g., 15º22.65′ N; 22º43.78′ E) using the WGS-84 coordinate system. No “N/A.” | I20: Major Must | M20: =IF(AND(J20<>"",ISBLANK(K20),ISBLANK(L20)),"Yes",IF(AND(K20<>"",ISBLANK(J20),ISBLANK(L20)),"No",IF(AND(L20<>"",ISBLANK(J20),ISBLANK(K20)),"N/A","not answered/error"))) -> not answered/error | Q20: Geographical coordinates of all sites:
A21: IFA | B21: IFA v6 Smart | C21: AQ | D21: AQ-Smart 02.05 | E21: AQ 02 INTERNAL DOCUMENTATION | F21: Records for auditing purposes are up-to-date. Records are kept for a minimum period of two years, unless a longer period is required. | G21: The producer shall keep up-to-date records, including those relating to food safety, for a minimum of two years, or a longer period depending on customer or legal requirements. If the shelf life of the product exceeds two years, records shall be retained for a period that exceeds the shelf life. Electronic records shall be valid and if they are used, the producer shall be responsible for maintaining back-ups of the information. Documents shall be securely stored, effectively controlled, and readily accessible. For the initial certification body (CB) audit, the producer shall keep records from at least three months prior to the date of the CB audit or from the day of registration, whichever is longer. New applicants shall have full records for each area covered by the registration with all of the activities related to GLOBALG.A.P. documentation required for this area. These records shall be available for the current cycle before the initial CB audit. No “N/A.” | I21: Major Must | M21: =IF(AND(J21<>"",ISBLANK(K21),ISBLANK(L21)),"Yes",IF(AND(K21<>"",ISBLANK(J21),ISBLANK(L21)),"No",IF(AND(L21<>"",ISBLANK(J21),ISBLANK(K21)),"N/A","not answered/error"))) -> not answered/error | Q21: examples of records verified: -XXXXXXX -XXXXXXX -XXXXXXX Describe where the records are kept/stored.
A22: IFA | B22: IFA v6 Smart | C22: AQ | D22: AQ-Smart 02.06 | E22: AQ 02 INTERNAL DOCUMENTATION | F22: A procedure is in place to manage and control documents and records. | G22: A procedure describing the management of documented information shall be implemented and maintained. A method of tracking document changes shall be established to ensure workers are accessing the most recent version. | I22: Major Must | M22: =IF(AND(J22<>"",ISBLANK(K22),ISBLANK(L22)),"Yes",IF(AND(K22<>"",ISBLANK(J22),ISBLANK(L22)),"No",IF(AND(L22<>"",ISBLANK(J22),ISBLANK(K22)),"N/A","not answered/error"))) -> not answered/error | Q22: Document identification name: code: revision: date:
A23: IFA | B23: IFA v6 Smart | C23: AQ | D23: AQ-Smart 02.07 | E23: AQ 02 INTERNAL DOCUMENTATION | F23: The producer completes a minimum of one self-assessment/internal audit annually to the standard. | G23: There shall be documented evidence that, in Option 1 individual producers, a self-assessment has been completed under the responsibility of the producer (this may be carried out by a person different from the producer). Self-assessments shall include all applicable principles and criteria, even when a subcontracted company carries them out. A documented self-assessment for individual producers shall contain comments regarding the evidence observed for all not applicable and non-compliant Major Must and Minor Must principles and criteria. For internal farm and quality management system (QMS) audits, comments shall follow “GLOBALG.A.P. general regulations – Rules for producer groups and multisite producers with QMS.” The self-assessment shall be completed before the certification body (CB) audit (see “GLOBALG.A.P. general regulations – Rules for individual producers”). No “N/A,” except for multisite producers with QMS and producer groups, which are covered by the internal QMS audit. | I23: Major Must | M23: =IF(AND(J23<>"",ISBLANK(K23),ISBLANK(L23)),"Yes",IF(AND(K23<>"",ISBLANK(J23),ISBLANK(L23)),"No",IF(AND(L23<>"",ISBLANK(J23),ISBLANK(K23)),"N/A","not answered/error"))) -> not answered/error | Q23: Date of self-assessment or internal farm audit: XXX Initials/abbreviation of person performing the internal audit:XXX
A24: IFA | B24: IFA v6 Smart | C24: AQ | D24: AQ-Smart 02.08 | E24: AQ 02 INTERNAL DOCUMENTATION | F24: Effective corrective actions are taken to address non-conformances detected during the self-assessments/internal audits. | G24: Corrective actions shall be documented. Any necessary changes shall be implemented. Compliance with all applicable Major Musts and at least 95% of applicable Minor Musts is required. “N/A” only if no non-conformances are detected during self-assessments/internal audits. | I24: Major Must | M24: =IF(AND(J24<>"",ISBLANK(K24),ISBLANK(L24)),"Yes",IF(AND(K24<>"",ISBLANK(J24),ISBLANK(L24)),"No",IF(AND(L24<>"",ISBLANK(J24),ISBLANK(K24)),"N/A","not answered/error"))) -> not answered/error | Q24: Number of non-compliances detected: Number of non-compliances still open:
A25: IFA | B25: IFA v6 Smart | C25: AQ | D25: AQ-Smart 02.09 | E25: AQ 02 INTERNAL DOCUMENTATION | F25: A continuous improvement plan is documented. | G25: A continuous improvement plan based on self-assessments/internal audits and certification body (CB) audits shall be documented. Continuous improvements can be shown as a reduction in overall non-conformances during self-assessments/internal audits, evaluation of a root cause analysis, documented actions, or other applicable activities. | I25: Major Must | M25: =IF(AND(J25<>"",ISBLANK(K25),ISBLANK(L25)),"Yes",IF(AND(K25<>"",ISBLANK(J25),ISBLANK(L25)),"No",IF(AND(L25<>"",ISBLANK(J25),ISBLANK(K25)),"N/A","not answered/error"))) -> not answered/error | Q25: Continuous improvement plan XX Dated YYYY/MM/DD Example of self-defined target XXXXXX - DATE OF ACHIEVEMENT PREVIEWED : XXX -
A26: IFA | B26: IFA v6 Smart | C26: AQ | D26: AQ-Smart 02.10 | E26: AQ 02 INTERNAL DOCUMENTATION | F26: There is evidence that a continuous improvement plan is implemented. | G26: A continuous improvement plan based on self-assessments/internal audits and certification body (CB) audits shall be implemented. Continuous improvements can be shown as a reduction in overall non-conformances during self-assessments/internal audits, resource management plans documenting improvements, or other applicable activities. | I26: Major Must | M26: =IF(AND(J26<>"",ISBLANK(K26),ISBLANK(L26)),"Yes",IF(AND(K26<>"",ISBLANK(J26),ISBLANK(L26)),"No",IF(AND(L26<>"",ISBLANK(J26),ISBLANK(K26)),"N/A","not answered/error"))) -> not answered/error | Q26: Document identification name: code: revision: date:
A27: IFA | B27: IFA v6 Smart | C27: AQ | D27: AQ-Smart 03.01 | E27: AQ 03 HYGIENE | F27: The farm has a documented hygiene risk assessment. | G27: The documented hygiene risk assessment shall be appropriate to the activities taking place on the farm and shall be reviewed annually and updated when changes (e.g., other activities) occur. No “N/A.” | I27: Major Must | M27: =IF(AND(J27<>"",ISBLANK(K27),ISBLANK(L27)),"Yes",IF(AND(K27<>"",ISBLANK(J27),ISBLANK(L27)),"No",IF(AND(L27<>"",ISBLANK(J27),ISBLANK(K27)),"N/A","not answered/error"))) -> not answered/error | Q27: Document identification name: code: revision: date: production stages covered: All production stages covered in the hygiene risk assessment are equivalent to those covered in the certificate, either performed by the producer or subcontracted. Detail/List all different production, harvest, and postharvest processes seen.
... A41: IFA | B41: IFA v6 Smart | C41: AQ | D41: AQ-Smart 04.02.06 | E41: AQ 04 WORKERS’ WELL-BEING: OCCUPATIONAL HEALTH, SAFETY, AND WELFARE | F41: Where workers with special duties are identified and competence in their tasks shall be demonstrated, records are available. | G41: Workers handling and/or administering veterinary medicines, chemicals, disinfectants, biocides, and/or other hazardous substances and all workers operating dangerous or complex equipment as defined in the risk assessment in AQ 04.01.01 shall have evidence of competence or details of other such qualifications. Records shall identify workers who carry out such tasks and can demonstrate competence (certificate of training and/or records of training with evidence of attendance). This shall include compliance with applicable legislation. Cross-reference with AQ 04.02.01. For workers administering medicines, evidence of adequate experience shall be in place. No “N/A.” | I41: Major Must | M41: =IF(AND(J41<>"",ISBLANK(K41),ISBLANK(L41)),"Yes",IF(AND(K41<>"",ISBLANK(J41),ISBLANK(L41)),"No",IF(AND(L41<>"",ISBLANK(J41),ISBLANK(K41)),"N/A","not answered/error"))) -> not answered/error | Q41: Topic of training: XXXXX Number of Workers: XXX; Traning Date: DD/MM/YY - Initials of the name of Trainer(s): XXXXX
A42: IFA | B42: IFA v6 Smart | C42: AQ | D42: AQ-Smart 04.03.01 | E42: AQ 04 WORKERS’ WELL-BEING: OCCUPATIONAL HEALTH, SAFETY, AND WELFARE | F42: Accident and emergency procedures are displayed and communicated. | G42: Instructions based on the accident and emergency procedures shall be clearly displayed in accessible and visible location(s) for workers, visitors, and subcontractors. A named person is assigned as responsible for such procedures. These instructions shall be available in the relevant language(s) of the workforce and/or in pictograms. The procedures shall be appropriate to the size and type of production and level of risk and take into account all applicable national legal requirements. Emergency evacuation equipment and survival gear (where required) shall be accessible and of sufficient quantity and quality. The procedures shall identify the following: - The farm address, map, or other location information (e.g., GPS coordinates) - The contact person(s) - An up-to-date list of relevant telephone numbers (police, ambulance, hospital, fire brigade, access to emergency health care on site or by means of transport, and the suppliers of electricity, water, and gas) - Emergency evacuation procedures, where applicable Examples of other procedures that can be included: - The location of the nearest means of communication (telephone, radio) - How and where to contact local medical services, hospitals, and other emergency services (Questions for contact with emergency services: WHERE did it happen? WHAT happened? HOW MANY injured people? WHAT kind of injuries? WHO is calling?) - The location of fire extinguisher(s) at structures and all buildings (including worker accommodation) that are considered a potential fire risk - The locations of emergency exits - Emergency cut-offs for electricity, gas, fuel, and water lines - How to record accidents and near misses and introduce preventive action - How to deal with accidents involving chemicals following safety data sheets (SDSs) | I42: Minor Must | M42: =IF(AND(J42<>"",ISBLANK(K42),ISBLANK(L42)),"Yes",IF(AND(K42<>"",ISBLANK(J42),ISBLANK(L42)),"No",IF(AND(L42<>"",ISBLANK(J42),ISBLANK(K42)),"N/A","not answered/error"))) -> not answered/error
A43: IFA | B43: IFA v6 Smart | C43: AQ | D43: AQ-Smart 04.03.02 | E43: AQ 04 WORKERS’ WELL-BEING: OCCUPATIONAL HEALTH, SAFETY, AND WELFARE | F43: Warning signs identify all potential hazards, emergency exits, and escape routes. | G43: Permanent and legible signs shall indicate potential hazards, emergency exits, and escape routes. This shall include indicating, where applicable: ongoing treatments, waste pits, fuel tanks, workshops, warning signs in all buildings or permanent structures showing emergency exits, escape routes, safety equipment (fire extinguisher, washing facilities, etc.) and safety alarms (fire, CO2, evacuation, tornado, etc.) and access doors of the storage facilities for chemicals. Fire exits and escape routes shall be kept open, accessible, and clear of obstacles to permit safe evacuation in case of an emergency. Warning signs shall be present and in the predominant language(s) of the workforce and/or in pictograms. No “N/A.” | I43: Minor Must | M43: =IF(AND(J43<>"",ISBLANK(K43),ISBLANK(L43)),"Yes",IF(AND(K43<>"",ISBLANK(J43),ISBLANK(L43)),"No",IF(AND(L43<>"",ISBLANK(J43),ISBLANK(K43)),"N/A","not answered/error"))) -> not answered/error
A44: IFA | B44: IFA v6 Smart | C44: AQ | D44: AQ-Smart 04.03.03 | E44: AQ 04 WORKERS’ WELL-BEING: OCCUPATIONAL HEALTH, SAFETY, AND WELFARE | F44: Safety advice for substances hazardous to workers’ health and safety is immediately available and accessible. | G44: Emergency information (website, telephone number, safety data sheet, etc.) on each hazardous substance shall be available and accessible in the appropriate locations. Cross-reference with AQ 19.01.02. | I44: Minor Must | M44: =IF(AND(J44<>"",ISBLANK(K44),ISBLANK(L44)),"Yes",IF(AND(K44<>"",ISBLANK(J44),ISBLANK(L44)),"No",IF(AND(L44<>"",ISBLANK(J44),ISBLANK(K44)),"N/A","not answered/error"))) -> not answered/error
A45: IFA | B45: IFA v6 Smart | C45: AQ | D45: AQ-Smart 04.03.04 | E45: AQ 04 WORKERS’ WELL-BEING: OCCUPATIONAL HEALTH, SAFETY, AND WELFARE | F45: First aid kits are accessible at all permanent sites and fields near the work. | G45: Complete and maintained first aid kits (i.e., complete and maintained according to local recommendations and appropriate to the activities being carried out) shall be available and accessible at all permanent sites and present in selected transport means (vessel, vehicle, etc.) where required by the risk assessment in AQ 04.01.01. | I45: Minor Must | M45: =IF(AND(J45<>"",ISBLANK(K45),ISBLANK(L45)),"Yes",IF(AND(K45<>"",ISBLANK(J45),ISBLANK(L45)),"No",IF(AND(L45<>"",ISBLANK(J45),ISBLANK(K45)),"N/A","not answered/error"))) -> not answered/error | Q45: first aid kit checked located in XXXXXX
A46: IFA | B46: IFA v6 Smart | C46: AQ | D46: AQ-Smart 04.03.05 | E46: AQ 04 WORKERS’ WELL-BEING: OCCUPATIONAL HEALTH, SAFETY, AND WELFARE | F46: There is always at least one person trained in first aid present on the farm whenever on-farm activities are being carried out. | G46: There shall always be at least one person trained in first aid (with valid training certificate) present on the farm whenever on-farm activities are being carried out. | I46: Minor Must | M46: =IF(AND(J46<>"",ISBLANK(K46),ISBLANK(L46)),"Yes",IF(AND(K46<>"",ISBLANK(J46),ISBLANK(L46)),"No",IF(AND(L46<>"",ISBLANK(J46),ISBLANK(K46)),"N/A","not answered/error"))) -> not answered/error
A47: IFA | B47: IFA v6 Smart | C47: AQ | D47: AQ-Smart 04.04.01 | E47: AQ 04 WORKERS’ WELL-BEING: OCCUPATIONAL HEALTH, SAFETY, AND WELFARE | F47: Workers, visitors, and subcontractors are equipped with suitable personal protective equipment (PPE). | G47: Complete sets of suitable PPE, enabling compliance with label instructions and/or legal requirements and/or requirements as authorized by a competent authority, shall be available on the farm, utilized, and in a good state of repair. Complying with label requirements and/or requirements in the risk assessment for on-farm operations may include use of some of the following: rubber boots or other appropriate footwear, waterproof clothing, protective overalls, rubber gloves, face masks, appropriate respiratory equipment (including replacement filters), ear and eye protection devices, life-jackets, etc. There shall be evidence that the provided PPE is used by the workers. No “N/A.” | I47: Major Must | M47: =IF(AND(J47<>"",ISBLANK(K47),ISBLANK(L47)),"Yes",IF(AND(K47<>"",ISBLANK(J47),ISBLANK(L47)),"No",IF(AND(L47<>"",ISBLANK(J47),ISBLANK(K47)),"N/A","not answered/error"))) -> not answered/error | Q47: PPE are available and suitable. Example of PPE used and the activity: -XXXXX for XXXXXX -XXXXX for XXXXXXX
A48: IFA | B48: IFA v6 Smart | C48: AQ | D48: AQ-Smart 04.04.02 | E48: AQ 04 WORKERS’ WELL-BEING: OCCUPATIONAL HEALTH, SAFETY, AND WELFARE | F48: Personal protective equipment (PPE) is maintained in clean conditions and stored appropriately so as not to pose any contamination risk to personal items. | G48: PPE shall be kept clean according to the type of use and degree of potential contamination and stored in a ventilated place. Protective clothing shall be laundered separately from personal clothing. Reusable gloves shall be washed before removal. Dirty and damaged PPE and expired filter cartridges shall be disposed of appropriately. Single-use items (gloves, overalls, etc.) shall be disposed of after one use. PPE shall be stored in a manner that prevents cross contamination with chemicals. No “N/A.” | I48: Major Must | M48: =IF(AND(J48<>"",ISBLANK(K48),ISBLANK(L48)),"Yes",IF(AND(K48<>"",ISBLANK(J48),ISBLANK(L48)),"No",IF(AND(L48<>"",ISBLANK(J48),ISBLANK(K48)),"N/A","not answered/error"))) -> not answered/error
A49: IFA | B49: IFA v6 Smart | C49: AQ | D49: AQ-Smart 04.05.01 | E49: AQ 04 WORKERS’ WELL-BEING: OCCUPATIONAL HEALTH, SAFETY, AND WELFARE | F49: A member of the management is clearly identifiable as responsible for the workers’ health, safety, and welfare. | G49: Documentation shall be available that clearly identifies and names the member of management who is responsible for ensuring compliance with and implementation of existing, current, and relevant national and local regulations on workers’ health, safety, and welfare. | I49: Major Must | M49: =IF(AND(J49<>"",ISBLANK(K49),ISBLANK(L49)),"Yes",IF(AND(K49<>"",ISBLANK(J49),ISBLANK(L49)),"No",IF(AND(L49<>"",ISBLANK(J49),ISBLANK(K49)),"N/A","not answered/error"))) -> not answered/error | Q49: Position of responsible for workers' health, safety and welfare.
A50: IFA | B50: IFA v6 Smart | C50: AQ | D50: AQ-Smart 04.05.02 | E50: AQ 04 WORKERS’ WELL-BEING: OCCUPATIONAL HEALTH, SAFETY, AND WELFARE | F50: There is communication between management and workers on issues related to their health, safety, and welfare. | G50: Records shall show that communication between management and workers about health, safety, and welfare issues can take place openly (i.e., without fear of intimidation or retaliation) and at least once a year. - It shall be emphasized to workers that, with reasonable justification, they shall remove themselves from unsafe work. The use of this right in good faith shall eliminate any retaliation or consequence to the workers. - If accidents, near misses, or other dangerous incidents occur, they shall be reported and the cause determined and discussed with the workers. - Management shall define corrective actions to prevent recurrence of similar incidents and clearly explain the corrective actions to the workers. - Workers shall explain to management situations where they feel exposed to risk. - Management shall explain procedures for eliminating or reducing risk detected by workers. The certification body (CB) auditor is not required to make judgments about the content, accuracy, or outcome of such communications. There shall be evidence that the concerns of the workers about health, safety, and welfare are being addressed. | I50: Major Must | M50: =IF(AND(J50<>"",ISBLANK(K50),ISBLANK(L50)),"Yes",IF(AND(K50<>"",ISBLANK(J50),ISBLANK(L50)),"No",IF(AND(L50<>"",ISBLANK(J50),ISBLANK(K50)),"N/A","not answered/error"))) -> not answered/error | Q50: Identification of the record of the last meeting name/code: XXX date/edition: XXX
A51: IFA | B51: IFA v6 Smart | C51: AQ | D51: AQ-Smart 04.05.03 | E51: AQ 04 WORKERS’ WELL-BEING: OCCUPATIONAL HEALTH, SAFETY, AND WELFARE | F51: On-site living quarters are compliant with applicable local regulations, habitable, and equipped with basic services and facilities. | G51: The on-site living quarters for the workers shall be habitable and have a sound roof, windows, and doors, as well as the basic services of potable water, hygienic toilets, cooking facilities, and drains. At a minimum, the quarters shall comply with the local health and safety regulations. Living quarters shall be away from any chemical hazards (including fire hazards, inflammable substances or hazards, etc.), biological hazards (mold, sewage, etc.), and physical hazards (noise, radiation, poor ventilation, extreme temperatures, etc.) identified in the risk assessment. If there are no drains, septic pits may be acceptable if compliant with local regulations. | I51: Major Must | M51: =IF(AND(J51<>"",ISBLANK(K51),ISBLANK(L51)),"Yes",IF(AND(K51<>"",ISBLANK(J51),ISBLANK(L51)),"No",IF(AND(L51<>"",ISBLANK(J51),ISBLANK(K51)),"N/A","not answered/error"))) -> not answered/error | Q51: If applicable, list the number of workers/families living on the farm.
A52: IFA | B52: IFA v6 Smart | C52: AQ | D52: AQ-Smart 04.05.04 | E52: AQ 04 WORKERS’ WELL-BEING: OCCUPATIONAL HEALTH, SAFETY, AND WELFARE | F52: Transportation provided to workers is safe. | G52: Transportation shall be safe for workers and take into account applicable safety requirements and regulations. | I52: Minor Must | M52: =IF(AND(J52<>"",ISBLANK(K52),ISBLANK(L52)),"Yes",IF(AND(K52<>"",ISBLANK(J52),ISBLANK(L52)),"No",IF(AND(L52<>"",ISBLANK(J52),ISBLANK(K52)),"N/A","not answered/error"))) -> not answered/error
A53: IFA | B53: IFA v6 Smart | C53: AQ | D53: AQ-Smart 04.05.05 | E53: AQ 04 WORKERS’ WELL-BEING: OCCUPATIONAL HEALTH, SAFETY, AND WELFARE | F53: The producer is compliant with the GRASP v2 add-on (assessed by the same certification body (CB) conducting the audit for the Integrated Farm Assurance (IFA) standard for aquaculture). | G53: The producer shall be compliant with the GRASP v2 add-on, covering all stages of production included under the certification: hatchery, grow-out, and any post-harvest handling done by the same legal entity as the farm. Regarding subcontractors, refer to the GRASP v2 general rules. A compliant GRASP v2 result shall be required in order to be in compliance with AQ 04.05.05 and to receive GLOBALG.A.P. certification for the IFA standard for aquaculture. This applies for all farmed aquatic species, regardless of whether destined to be labeled or only having valid GLOBALG.A.P. certification. No “N/A.” | I53: Major Must | M53: =IF(AND(J53<>"",ISBLANK(K53),ISBLANK(L53)),"Yes",IF(AND(K53<>"",ISBLANK(J53),ISBLANK(L53)),"No",IF(AND(L53<>"",ISBLANK(J53),ISBLANK(K53)),"N/A","not answered/error"))) -> not answered/error | Q53: Date(s) of GRASP assessment: Date of Letter of conformance:
A54: IFA | B54: IFA v6 Smart | C54: AQ | D54: AQ-Smart 05.01 | E54: AQ 05 OUTSOURCED ACTIVITIES (SUBCONTRACTORS) | F54: The producer ensures that outsourced activities comply with the principles and criteria of the standard which are relevant to the services provided. | G54: The producer shall verify that tasks performed by subcontractors are compliant with the relevant principles and criteria of this standard. This verification shall be recorded and made available during the certification body (CB) audit. Based on the subcontractor services: i) GLOBALG.A.P. approved CB is allowed to verify compliance through a physical assessment, or ii) A GLOBALG.A.P. approved CB may assess the subcontractor directly. The subcontractor shall receive a letter of conformance from the CB with the following information: 1) Date of CB assessment 2) Name of the CB 3) Auditor name 4) Details of the subcontractor 5) List of the assessed principles and criteria Other certificates issued to subcontractors against standards that are not officially recognized by GLOBALG.A.P. are not valid evidence of compliance with GLOBALG.A.P. All subcontractors physically handling live farmed aquatic species shall have evidence of animal welfare training. Any activity performed by subcontractors shall follow legislation, including when outside the farm (subcontracted companies removing waste, sludge, old equipment, etc.). | I54: Major Must | M54: =IF(AND(J54<>"",ISBLANK(K54),ISBLANK(L54)),"Yes",IF(AND(K54<>"",ISBLANK(J54),ISBLANK(L54)),"No",IF(AND(L54<>"",ISBLANK(J54),ISBLANK(K54)),"N/A","not answered/error"))) -> not answered/error | Q54: Examples of subcontracted activities checked: Specific standard criteria related to the subcontracted: Identify which of the three situations applies (1, 2 or 3):
...

Sheet Audit Result
A3: GGN*: | E3: IFA v6 Smart Aquaculture
A4: Audit Date* | E4: Audited Company*:
A5: Principle | B5: Level | C5: Original Answer | D5: Justification | E5: Due date | F5: Corrective actions* | G5: Closed? (x)* | H5: Status | I5: Closed by* | J5: Closed on* | K5: Comments*
A6: ='CL - IFA v6 Smart - AQ'!D10 -> AQ-Smart 01.01.01 | B6: ='CL - IFA v6 Smart - AQ'!I10 -> Major Must | C6: =IF('CL - IFA v6 Smart - AQ'!M10 = 0,"",'CL - IFA v6 Smart - AQ'!M10) -> not answered/error | D6: =IF('CL - IFA v6 Smart - AQ'!Q10 = 0, "",'CL - IFA v6 Smart - AQ'!Q10) -> Confirmation that a map is available and that it clearly identifies all sites. If physical signs are in place, this shall be recorded. | E6: =IF('CL - IFA v6 Smart - AQ'!R10 = 0,"",'CL - IFA v6 Smart - AQ'!R10) | H6: =IF('Audit Result'!C6 = "No", IF('Audit Result'!G6 = "x", "Closed", "Open"), "")
A7: ='CL - IFA v6 Smart - AQ'!D11 -> AQ-Smart 01.01.02 | B7: ='CL - IFA v6 Smart - AQ'!I11 -> Major Must | C7: =IF('CL - IFA v6 Smart - AQ'!M11 = 0,"",'CL - IFA v6 Smart - AQ'!M11) -> not answered/error | D7: =IF('CL - IFA v6 Smart - AQ'!Q11 = 0, "",'CL - IFA v6 Smart - AQ'!Q11) -> Identification of the site and the period where all history of activities were revised. | E7: =IF('CL - IFA v6 Smart - AQ'!R11 = 0,"",'CL - IFA v6 Smart - AQ'!R11) | H7: =IF('Audit Result'!C7 = "No", IF('Audit Result'!G7 = "x", "Closed", "Open"), "")
A8: ='CL - IFA v6 Smart - AQ'!D12 -> AQ-Smart 01.02.01 | B8: ='CL - IFA v6 Smart - AQ'!I12 -> Major Must | C8: =IF('CL - IFA v6 Smart - AQ'!M12 = 0,"",'CL - IFA v6 Smart - AQ'!M12) -> not answered/error | D8: =IF('CL - IFA v6 Smart - AQ'!Q12 = 0, "",'CL - IFA v6 Smart - AQ'!Q12) -> A documented risk assessment is available with a list A list of all activities potentially affecting the aquaculture farm: potential physical, chemical (including allergens), and biological hazards. Document identification name: code: revision: date: | E8: =IF('CL - IFA v6 Smart - AQ'!R12 = 0,"",'CL - IFA v6 Smart - AQ'!R12) | H8: =IF('Audit Result'!C8 = "No", IF('Audit Result'!G8 = "x", "Closed", "Open"), "")
A9: ='CL - IFA v6 Smart - AQ'!D13 -> AQ-Smart 01.02.02 | B9: ='CL - IFA v6 Smart - AQ'!I13 -> Major Must | C9: =IF('CL - IFA v6 Smart - AQ'!M13 = 0,"",'CL - IFA v6 Smart - AQ'!M13) -> not answered/error | D9: =IF('CL - IFA v6 Smart - AQ'!Q13 = 0, "",'CL - IFA v6 Smart - AQ'!Q13) -> A management pla address the risks identified in AQ 01.02.01. Document identification name: code: revision: date: | E9: =IF('CL - IFA v6 Smart - AQ'!R13 = 0,"",'CL - IFA v6 Smart - AQ'!R13) | H9: =IF('Audit Result'!C9 = "No", IF('Audit Result'!G9 = "x", "Closed", "Open"), "")
A10: ='CL - IFA v6 Smart - AQ'!D14 -> AQ-Smart 01.02.03 | B10: ='CL - IFA v6 Smart - AQ'!I14 -> Major Must | C10: =IF('CL - IFA v6 Smart - AQ'!M14 = 0,"",'CL - IFA v6 Smart - AQ'!M14) -> not answered/error | D10: =IF('CL - IFA v6 Smart - AQ'!Q14 = 0, "",'CL - IFA v6 Smart - AQ'!Q14) | E10: =IF('CL - IFA v6 Smart - AQ'!R14 = 0,"",'CL - IFA v6 Smart - AQ'!R14) | H10: =IF('Audit Result'!C10 = "No", IF('Audit Result'!G10 = "x", "Closed", "Open"), "")
A11: ='CL - IFA v6 Smart - AQ'!D15 -> AQ-Smart 01.03.01 | B11: ='CL - IFA v6 Smart - AQ'!I15 -> Major Must | C11: =IF('CL - IFA v6 Smart - AQ'!M15 = 0,"",'CL - IFA v6 Smart - AQ'!M15) -> not answered/error | D11: =IF('CL - IFA v6 Smart - AQ'!Q15 = 0, "",'CL - IFA v6 Smart - AQ'!Q15) | E11: =IF('CL - IFA v6 Smart - AQ'!R15 = 0,"",'CL - IFA v6 Smart - AQ'!R15) | H11: =IF('Audit Result'!C11 = "No", IF('Audit Result'!G11 = "x", "Closed", "Open"), "")
A12: ='CL - IFA v6 Smart - AQ'!D16 -> AQ-Smart 01.03.02 | B12: ='CL - IFA v6 Smart - AQ'!I16 -> Major Must | C12: =IF('CL - IFA v6 Smart - AQ'!M16 = 0,"",'CL - IFA v6 Smart - AQ'!M16) -> not answered/error | D12: =IF('CL - IFA v6 Smart - AQ'!Q16 = 0, "",'CL - IFA v6 Smart - AQ'!Q16) -> Document identification name/type of licence: code: revision: date: institution that issue the license: Date of validity of the license/permit. | E12: =IF('CL - IFA v6 Smart - AQ'!R16 = 0,"",'CL - IFA v6 Smart - AQ'!R16) | H12: =IF('Audit Result'!C12 = "No", IF('Audit Result'!G12 = "x", "Closed", "Open"), "")
A13: ='CL - IFA v6 Smart - AQ'!D17 -> AQ-Smart 02.01 | B13: ='CL - IFA v6 Smart - AQ'!I17 -> Major Must | C13: =IF('CL - IFA v6 Smart - AQ'!M17 = 0,"",'CL - IFA v6 Smart - AQ'!M17) -> not answered/error | D13: =IF('CL - IFA v6 Smart - AQ'!Q17 = 0, "",'CL - IFA v6 Smart - AQ'!Q17) -> all records verified show as a minimum three months of recording. Example: XXXXXXXXXXX For consecutive audits, report: "Consecutive audit." | E13: =IF('CL - IFA v6 Smart - AQ'!R17 = 0,"",'CL - IFA v6 Smart - AQ'!R17) | H13: =IF('Audit Result'!C13 = "No", IF('Audit Result'!G13 = "x", "Closed", "Open"), "")
A14: ='CL - IFA v6 Smart - AQ'!D18 -> AQ-Smart 02.02 | B14: ='CL - IFA v6 Smart - AQ'!I18 -> Major Must | C14: =IF('CL - IFA v6 Smart - AQ'!M18 = 0,"",'CL - IFA v6 Smart - AQ'!M18) -> not answered/error | D14: =IF('CL - IFA v6 Smart - AQ'!Q18 = 0, "",'CL - IFA v6 Smart - AQ'!Q18) -> Document identification name: code: revision: date: | E14: =IF('CL - IFA v6 Smart - AQ'!R18 = 0,"",'CL - IFA v6 Smart - AQ'!R18) | H14: =IF('Audit Result'!C14 = "No", IF('Audit Result'!G14 = "x", "Closed", "Open"), "")
A15: ='CL - IFA v6 Smart - AQ'!D19 -> AQ-Smart 02.03 | B15: ='CL - IFA v6 Smart - AQ'!I19 -> Major Must | C15: =IF('CL - IFA v6 Smart - AQ'!M19 = 0,"",'CL - IFA v6 Smart - AQ'!M19) -> not answered/error | D15: =IF('CL - IFA v6 Smart - AQ'!Q19 = 0, "",'CL - IFA v6 Smart - AQ'!Q19) -> Document identification name: code: revision: date: | E15: =IF('CL - IFA v6 Smart - AQ'!R19 = 0,"",'CL - IFA v6 Smart - AQ'!R19) | H15: =IF('Audit Result'!C15 = "No", IF('Audit Result'!G15 = "x", "Closed", "Open"), "")
A16: ='CL - IFA v6 Smart - AQ'!D20 -> AQ-Smart 02.04 | B16: ='CL - IFA v6 Smart - AQ'!I20 -> Major Must | C16: =IF('CL - IFA v6 Smart - AQ'!M20 = 0,"",'CL - IFA v6 Smart - AQ'!M20) -> not answered/error | D16: =IF('CL - IFA v6 Smart - AQ'!Q20 = 0, "",'CL - IFA v6 Smart - AQ'!Q20) -> Geographical coordinates of all sites: | E16: =IF('CL - IFA v6 Smart - AQ'!R20 = 0,"",'CL - IFA v6 Smart - AQ'!R20) | H16: =IF('Audit Result'!C16 = "No", IF('Audit Result'!G16 = "x", "Closed", "Open"), "")
A17: ='CL - IFA v6 Smart - AQ'!D21 -> AQ-Smart 02.05 | B17: ='CL - IFA v6 Smart - AQ'!I21 -> Major Must | C17: =IF('CL - IFA v6 Smart - AQ'!M21 = 0,"",'CL - IFA v6 Smart - AQ'!M21) -> not answered/error | D17: =IF('CL - IFA v6 Smart - AQ'!Q21 = 0, "",'CL - IFA v6 Smart - AQ'!Q21) -> examples of records verified: -XXXXXXX -XXXXXXX -XXXXXXX Describe where the records are kept/stored. | E17: =IF('CL - IFA v6 Smart - AQ'!R21 = 0,"",'CL - IFA v6 Smart - AQ'!R21) | H17: =IF('Audit Result'!C17 = "No", IF('Audit Result'!G17 = "x", "Closed", "Open"), "")
... A262: ='CL - IFA v6 Smart - AQ'!D266 -> AQ-Smart 28.06.02 | B262: ='CL - IFA v6 Smart - AQ'!I266 -> Major Must | C262: =IF('CL - IFA v6 Smart - AQ'!M266 = 0,"",'CL - IFA v6 Smart - AQ'!M266) -> not answered/error | D262: =IF('CL - IFA v6 Smart - AQ'!Q266 = 0, "",'CL - IFA v6 Smart - AQ'!Q266) | E262: =IF('CL - IFA v6 Smart - AQ'!R266 = 0,"",'CL - IFA v6 Smart - AQ'!R266) | H262: =IF('Audit Result'!C262 = "No", IF('Audit Result'!G262 = "x", "Closed", "Open"), "")
A273: Summary
A274: Original calculation after the end of Audit
A275: Type | B275: Total Amount Checklist | C275: Yes | D275: No | E275: N/A | F275: Not answered | G275: NC Closed | H275: % Compliance
A276: Major | B276: =COUNTIF('CL - IFA v6 Smart - AQ'!I10:'CL - IFA v6 Smart - AQ'!I266, "Major Must") -> 230 | C276: =COUNTIFS('CL - IFA v6 Smart - AQ'!I10:'CL - IFA v6 Smart - AQ'!I266, "Major Must",'CL - IFA v6 Smart - AQ'!M10:'CL - IFA v6 Smart - AQ'!M266, "Yes") -> 0 | D276: =COUNTIFS('CL - IFA v6 Smart - AQ'!I10:'CL - IFA v6 Smart - AQ'!I266, "Major Must",'CL - IFA v6 Smart - AQ'!M10:'CL - IFA v6 Smart - AQ'!M266, "No") -> 0 | E276: =COUNTIFS('CL - IFA v6 Smart - AQ'!I10:'CL - IFA v6 Smart - AQ'!I266, "Major Must",'CL - IFA v6 Smart - AQ'!M10:'CL - IFA v6 Smart - AQ'!M266, "N/A") -> 0 | F276: =B276-(C276+D276+E276) -> 230 | H276: =IFERROR(IF((C276+G276)/(B276-E276) = 0, " - ", (C276+G276)/(B276-E276))," - ") -> -
A277: Minor | B277: =COUNTIF('CL - IFA v6 Smart - AQ'!I10:'CL - IFA v6 Smart - AQ'!I266, "Minor Must") -> 22 | C277: =COUNTIFS('CL - IFA v6 Smart - AQ'!I10:'CL - IFA v6 Smart - AQ'!I266, "Minor Must",'CL - IFA v6 Smart - AQ'!M10:'CL - IFA v6 Smart - AQ'!M266, "Yes") -> 0 | D277: =COUNTIFS('CL - IFA v6 Smart - AQ'!I10:'CL - IFA v6 Smart - AQ'!I266, "Minor Must",'CL - IFA v6 Smart - AQ'!M10:'CL - IFA v6 Smart - AQ'!M266, "No") -> 0 | E277: =COUNTIFS('CL - IFA v6 Smart - AQ'!I10:'CL - IFA v6 Smart - AQ'!I266, "Minor Must",'CL - IFA v6 Smart - AQ'!M10:'CL - IFA v6 Smart - AQ'!M266, "N/A") -> 0 | F277: =B277-(C277+D277+E277) -> 22 | H277: =IFERROR(IF((C277+G277)/(B277-E277) = 0, " - ", (C277+G277)/(B277-E277))," - ") -> -
A278: Recommendation | B278: =COUNTIF('CL - IFA v6 Smart - AQ'!I10:'CL - IFA v6 Smart - AQ'!I266, "Recommendation") -> 5 | C278: =COUNTIFS('CL - IFA v6 Smart - AQ'!I10:'CL - IFA v6 Smart - AQ'!I266, "Recommendation",'CL - IFA v6 Smart - AQ'!M10:'CL - IFA v6 Smart - AQ'!M266, "Yes") -> 0 | D278: =COUNTIFS('CL - IFA v6 Smart - AQ'!I10:'CL - IFA v6 Smart - AQ'!I266, "Recommendation",'CL - IFA v6 Smart - AQ'!M10:'CL - IFA v6 Smart - AQ'!M266, "No") -> 0 | E278: =COUNTIFS('CL - IFA v6 Smart - AQ'!I10:'CL - IFA v6 Smart - AQ'!I266, "Recommendation",'CL - IFA v6 Smart - AQ'!M10:'CL - IFA v6 Smart - AQ'!M266, "N/A") -> 0 | F278: =B278-(C278+D278+E278) -> 5 | H278: =IFERROR(IF((C278+G278)/(B278-E278) = 0, " - ", (C278+G278)/(B278-E278))," - ") -> -
A280: Revised calculation after Non-Compliance points are closed
A281: Type | B281: Total Amount Checklist | C281: Yes | D281: No | E281: N/A | F281: Not answered | G281: NC Closed | H281: % Compliance
A282: Major | B282: =COUNTIF('CL - IFA v6 Smart - AQ'!I10:'CL - IFA v6 Smart - AQ'!I266, "Major Must") -> 230 | C282: =COUNTIFS('CL - IFA v6 Smart - AQ'!I10:'CL - IFA v6 Smart - AQ'!I266, "Major Must",'CL - IFA v6 Smart - AQ'!M10:'CL - IFA v6 Smart - AQ'!M266, "Yes") -> 0 | D282: =COUNTIFS('CL - IFA v6 Smart - AQ'!I10:'CL - IFA v6 Smart - AQ'!I266, "Major Must",'CL - IFA v6 Smart - AQ'!M10:'CL - IFA v6 Smart - AQ'!M266, "No") -> 0 | E282: =COUNTIFS('CL - IFA v6 Smart - AQ'!I10:'CL - IFA v6 Smart - AQ'!I266, "Major Must",'CL - IFA v6 Smart - AQ'!M10:'CL - IFA v6 Smart - AQ'!M266, "N/A") -> 0 | F282: =B282-(C282+D282+E282) -> 230 | G282: =COUNTIFS(B6:B262,"Major Must",H6:H262, "Closed") -> 0 | H282: =IFERROR(IF((C282+G282)/(B282-E282) = 0, " - ", (C282+G282)/(B282-E282))," - ") -> -
A283: Minor | B283: =COUNTIF('CL - IFA v6 Smart - AQ'!I10:'CL - IFA v6 Smart - AQ'!I266, "Minor Must") -> 22 | C283: =COUNTIFS('CL - IFA v6 Smart - AQ'!I10:'CL - IFA v6 Smart - AQ'!I266, "Minor Must",'CL - IFA v6 Smart - AQ'!M10:'CL - IFA v6 Smart - AQ'!M266, "Yes") -> 0 | D283: =COUNTIFS('CL - IFA v6 Smart - AQ'!I10:'CL - IFA v6 Smart - AQ'!I266, "Minor Must",'CL - IFA v6 Smart - AQ'!M10:'CL - IFA v6 Smart - AQ'!M266, "No") -> 0 | E283: =COUNTIFS('CL - IFA v6 Smart - AQ'!I10:'CL - IFA v6 Smart - AQ'!I266, "Minor Must",'CL - IFA v6 Smart - AQ'!M10:'CL - IFA v6 Smart - AQ'!M266, "N/A") -> 0 | F283: =B283-(C283+D283+E283) -> 22 | G283: =COUNTIFS(B6:B262,"Minor Must",H6:H262, "Closed") -> 0 | H283: =IFERROR(IF((C283+G283)/(B283-E283) = 0, " - ", (C283+G283)/(B283-E283))," - ") -> -
A284: Recommendation | B284: =COUNTIF('CL - IFA v6 Smart - AQ'!I10:'CL - IFA v6 Smart - AQ'!I266, "Recommendation") -> 5 | C284: =COUNTIFS('CL - IFA v6 Smart - AQ'!I10:'CL - IFA v6 Smart - AQ'!I266, "Recommendation",'CL - IFA v6 Smart - AQ'!M10:'CL - IFA v6 Smart - AQ'!M266, "Yes") -> 0 | D284: =COUNTIFS('CL - IFA v6 Smart - AQ'!I10:'CL - IFA v6 Smart - AQ'!I266, "Recommendation",'CL - IFA v6 Smart - AQ'!M10:'CL - IFA v6 Smart - AQ'!M266, "No") -> 0 | E284: =COUNTIFS('CL - IFA v6 Smart - AQ'!I10:'CL - IFA v6 Smart - AQ'!I266, "Recommendation",'CL - IFA v6 Smart - AQ'!M10:'CL - IFA v6 Smart - AQ'!M266, "N/A") -> 0 | F284: =B284-(C284+D284+E284) -> 5 | G284: =COUNTIFS(B6:B262,"Recommendation",H6:H262, "Closed") -> 0 | H284: =IFERROR(IF((C284+G284)/(B284-E284) = 0, " - ", (C284+G284)/(B284-E284))," - ") -> -

Sheet IFA Inspection Guideline

Sheet Info _ Workers welfare P&Cs
A1: LIST OF CRITERIA RELATED TO WORKERS SAFETY, WORKERS HEALTH AND WORKERS WELLBEING in IFA FO Smart | E1: LIST OF CRITERIA RELATED TO WORKERS SAFETY, WORKERS HEALTH AND WORKERS WELLBEING in IFA AQ GFS/SMART | I1: LIST OF CRITERIA RELATED TO WORKERS SAFETY, WORKERS HEALTH AND WORKERS WELLBEING in IFA v6 FV Smart and GFS
A3: Principle Number | B3: Topic | C3: Level | E3: Principle Number | F3: Topic | G3: Level | I3: Principle Number | J3: Topic | K3: Level
A4: FO 01.04.01 | B4: Records training kept | C4: minor | E4: AQ 04.03.01 | F4: Accident procedure | G4: minor | I4: FV-SMART & GFS 03.01 | J4: Role WHS representative | K4: minor (Major in GFS)
A5: FO 07.09.01 | B5: Equipment fit for use | C5: minor | E5: AQ 04.03.03 | F5: Safety Advice to workers | G5: minor | I5: FV-SMART & GFS 20.02.02 | J5: Safety Advice to workers | K5: minor
A6: FO 13.06 | B6: Toilets and washing facilities | C6: minor | E6: AQ 04.03.04 | F6: First aid kits available | G6: minor | I6: FV-SMART & GFS 20.02.03 | J6: First aid kits available | K6: minor
A7: FO 12.01.02 | B7: WHS procedures | C7: minor | E7: AQ 04.03.05 | F7: Person trained First Aid | G7: minor | I7: FV-SMART & GFS 20.02.04 | J7: Person trained First Aid | K7: minor
A8: FO 12.01.03 | B8: Training WHS | C8: minor | E8: AQ 04.05.04 | F8: Transportation safe | G8: minor | I8: FV-SMART & GFS 20.03.03 | J8: Equipment used by workers | K8: minor
A9: FO 12.02.01 | B9: Safety Advice to workers | C9: minor | E9: AQ 19.03.01 | F9: PPP transported safely | G9: minor | I9: FV-SMART & GFS 20.03.04 | J9: Changing facilities available | K9: minor
A10: FO 12.02.02 | B10: First aid kits available | C10: minor | I10: FV-SMART & GFS 20.04.01 | J10: Comm WHS worker/management | K10: minor
A11: FO 12.02.03 | B11: Person trained First Aid | C11: minor | I11: FV-SMART & GFS 20.04.04 | J11: Transportation safe | K11: minor
A12: FO 12.03.03 | B12: Equipment used by workers | C12: minor | I12: FV-SMART & GFS 25.06 | J12: Water correctly disposed | K12: minor
A13: FO 12.03.04 | B13: Changing facilities available | C13: minor | I13: FV-SMART & GFS 29.01.06 | J13: Name applicators | K13: minor
A14: FO 12.03.05 | B14: Comm WHS worker/management | C14: minor | I14: FV-SMART & GFS 32.04.03 | J14: Containers kept safely | K14: minor
A15: FO 13.05 | B15: Transportation safe | C15: minor | I15: FV-SMART & GFS 32.04.04 | J15: Containers disposed correctly | K15: minor
A16: FO 09.06 | B16: Water correctly disposed | C16: minor | I16: FV-SMART & GFS 32.09.02 | J16: PPP storage is safe | K16: minor
A17: FO 04.06.01 | B17: Name applicators | C17: minor | I17: FV-SMART & GFS 32.09.03 | J17: PPS storage does not pose risk | K17: minor
A18: FO 07.06.02 | B18: Containers reused | C18: minor | I18: FV-SMART & GFS 32.09.05 | J18: Storage has light | K18: minor
A19: FO 07.06.03 | B19: Containers kept safely | C19: minor | I19: FV-SMART & GFS 32.10.01 | J19: Access to health checks | K19: minor
A20: FO 07.06.04 | B20: Containers disposed correctly | C20: minor | I20: FV-SMART & GFS 32.10.03 | J20: Accident procedure | K20: minor
A21: FO 07.04.02 | B21: PPS storage does not pose risk | C21: minor | I21: FV-SMART & GFS 32.10.04 | J21: Facilities deal with accidents | K21: minor
A22: FO 07.04.03 | B22: Storage has light | C22: minor | I22: FV-SMART & GFS 32.10.05 | J22: PPP transported safely | K22: minor
A23: FO 07.04.06 | B23: Accident procedure | C23: minor
A24: FO 07.04.07 | B24: Facilities deal with accidents | C24: minor
A25: FO 07.05.02 | B25: PPP transported safely | C25: minor
